[2019-11-15 20:09:09] [ERROR] red: Exception in command 'layton'
Traceback (most recent call last):
  File "/usr/local/lib/python3.7/site-packages/discord/ext/commands/core.py", line 79, in wrapped
    ret = await coro(*args, **kwargs)
  File "/Users/vutheduc/Documents/Projects/PuzzleSoc/Social/Discord/CrypticBot/mycogs/layton/layton.py", line 76, in layton
    continue_ = await self.wait_for_answer(answers, 1, 900)
  File "/Users/vutheduc/Documents/Projects/PuzzleSoc/Social/Discord/CrypticBot/mycogs/layton/layton.py", line 106, in wait_for_answer
    clue, ans_len = self._current_puzzle
ValueError: too many values to unpack (expected 2)
[2019-11-15 20:10:11] [ERROR] red: Exception in command 'layton'
Traceback (most recent call last):
  File "/usr/local/lib/python3.7/site-packages/discord/ext/commands/core.py", line 79, in wrapped
    ret = await coro(*args, **kwargs)
  File "/Users/vutheduc/Documents/Projects/PuzzleSoc/Social/Discord/CrypticBot/mycogs/layton/layton.py", line 68, in layton
    self._current_puzzle = grab_puzzle(id_)
  File "/Users/vutheduc/Documents/Projects/PuzzleSoc/Social/Discord/CrypticBot/mycogs/layton/layton.py", line 255, in grab_puzzle
    sol_txts += p.get_text(),
AttributeError: 'NoneType' object has no attribute 'get_text'
[2019-11-15 20:10:23] [ERROR] red: Exception in command 'layton'
Traceback (most recent call last):
  File "/usr/local/lib/python3.7/site-packages/discord/ext/commands/core.py", line 79, in wrapped
    ret = await coro(*args, **kwargs)
  File "/Users/vutheduc/Documents/Projects/PuzzleSoc/Social/Discord/CrypticBot/mycogs/layton/layton.py", line 68, in layton
    self._current_puzzle = grab_puzzle(id_)
  File "/Users/vutheduc/Documents/Projects/PuzzleSoc/Social/Discord/CrypticBot/mycogs/layton/layton.py", line 255, in grab_puzzle
    sol_txts += p.get_text(),
AttributeError: 'NoneType' object has no attribute 'get_text'
[2019-11-15 20:10:26] [ERROR] red: Exception in command 'layton'
Traceback (most recent call last):
  File "/usr/local/lib/python3.7/site-packages/discord/ext/commands/core.py", line 79, in wrapped
    ret = await coro(*args, **kwargs)
  File "/Users/vutheduc/Documents/Projects/PuzzleSoc/Social/Discord/CrypticBot/mycogs/layton/layton.py", line 76, in layton
    continue_ = await self.wait_for_answer(answers, 1, 900)
  File "/Users/vutheduc/Documents/Projects/PuzzleSoc/Social/Discord/CrypticBot/mycogs/layton/layton.py", line 108, in wait_for_answer
    "message", check=self.check_answer(answers), timeout=delay
  File "/Users/vutheduc/Documents/Projects/PuzzleSoc/Social/Discord/CrypticBot/mycogs/layton/layton.py", line 121, in check_answer
    answers = [ans.lower() for ans in answers]
UnboundLocalError: local variable 'answers' referenced before assignment
[2019-11-15 20:10:52] [ERROR] red: Exception in command 'layton'
Traceback (most recent call last):
  File "/usr/local/lib/python3.7/site-packages/discord/ext/commands/core.py", line 79, in wrapped
    ret = await coro(*args, **kwargs)
  File "/Users/vutheduc/Documents/Projects/PuzzleSoc/Social/Discord/CrypticBot/mycogs/layton/layton.py", line 68, in layton
    self._current_puzzle = grab_puzzle(id_)
  File "/Users/vutheduc/Documents/Projects/PuzzleSoc/Social/Discord/CrypticBot/mycogs/layton/layton.py", line 255, in grab_puzzle
    sol_txts += p.get_text(),
AttributeError: 'NoneType' object has no attribute 'get_text'
[2019-11-15 20:10:56] [ERROR] red: Exception in command 'layton'
Traceback (most recent call last):
  File "/usr/local/lib/python3.7/site-packages/discord/ext/commands/core.py", line 79, in wrapped
    ret = await coro(*args, **kwargs)
  File "/Users/vutheduc/Documents/Projects/PuzzleSoc/Social/Discord/CrypticBot/mycogs/layton/layton.py", line 76, in layton
    continue_ = await self.wait_for_answer(answers, 1, 900)
  File "/Users/vutheduc/Documents/Projects/PuzzleSoc/Social/Discord/CrypticBot/mycogs/layton/layton.py", line 108, in wait_for_answer
    "message", check=self.check_answer(answers), timeout=delay
  File "/Users/vutheduc/Documents/Projects/PuzzleSoc/Social/Discord/CrypticBot/mycogs/layton/layton.py", line 121, in check_answer
    answers = [ans.lower() for ans in answers]
  File "/Users/vutheduc/Documents/Projects/PuzzleSoc/Social/Discord/CrypticBot/mycogs/layton/layton.py", line 121, in <listcomp>
    answers = [ans.lower() for ans in answers]
AttributeError: 'NoneType' object has no attribute 'lower'
[2019-11-15 20:11:48] [ERROR] red: Exception in command 'layton'
Traceback (most recent call last):
  File "/usr/local/lib/python3.7/site-packages/discord/ext/commands/core.py", line 79, in wrapped
    ret = await coro(*args, **kwargs)
  File "/Users/vutheduc/Documents/Projects/PuzzleSoc/Social/Discord/CrypticBot/mycogs/layton/layton.py", line 68, in layton
    self._current_puzzle = grab_puzzle(id_)
  File "/Users/vutheduc/Documents/Projects/PuzzleSoc/Social/Discord/CrypticBot/mycogs/layton/layton.py", line 255, in grab_puzzle
    sol_txts += p.get_text(),
AttributeError: 'NoneType' object has no attribute 'get_text'
[2019-11-15 20:11:54] [ERROR] red: Exception in command 'layton'
Traceback (most recent call last):
  File "/usr/local/lib/python3.7/site-packages/discord/ext/commands/core.py", line 79, in wrapped
    ret = await coro(*args, **kwargs)
  File "/Users/vutheduc/Documents/Projects/PuzzleSoc/Social/Discord/CrypticBot/mycogs/layton/layton.py", line 68, in layton
    self._current_puzzle = grab_puzzle(id_)
  File "/Users/vutheduc/Documents/Projects/PuzzleSoc/Social/Discord/CrypticBot/mycogs/layton/layton.py", line 255, in grab_puzzle
    sol_txts += p.get_text(),
AttributeError: 'NoneType' object has no attribute 'get_text'
[2019-11-15 20:13:01] [ERROR] red: Exception in command 'layton'
Traceback (most recent call last):
  File "/usr/local/lib/python3.7/site-packages/discord/ext/commands/core.py", line 79, in wrapped
    ret = await coro(*args, **kwargs)
  File "/Users/vutheduc/Documents/Projects/PuzzleSoc/Social/Discord/CrypticBot/mycogs/layton/layton.py", line 65, in layton
    if self._current_puzzle is None or not self._current_puzzle['set_answer']:
KeyError: 'set_answer'
[2019-11-15 20:13:03] [ERROR] red: Exception in command 'layton'
Traceback (most recent call last):
  File "/usr/local/lib/python3.7/site-packages/discord/ext/commands/core.py", line 79, in wrapped
    ret = await coro(*args, **kwargs)
  File "/Users/vutheduc/Documents/Projects/PuzzleSoc/Social/Discord/CrypticBot/mycogs/layton/layton.py", line 65, in layton
    if self._current_puzzle is None or not self._current_puzzle['set_answer']:
KeyError: 'set_answer'
[2019-11-15 20:13:06] [ERROR] red: Exception in command 'layton'
Traceback (most recent call last):
  File "/usr/local/lib/python3.7/site-packages/discord/ext/commands/core.py", line 79, in wrapped
    ret = await coro(*args, **kwargs)
  File "/Users/vutheduc/Documents/Projects/PuzzleSoc/Social/Discord/CrypticBot/mycogs/layton/layton.py", line 65, in layton
    if self._current_puzzle is None or not self._current_puzzle['set_answer']:
KeyError: 'set_answer'
[2019-11-15 20:13:08] [ERROR] red: Exception in command 'layton'
Traceback (most recent call last):
  File "/usr/local/lib/python3.7/site-packages/discord/ext/commands/core.py", line 79, in wrapped
    ret = await coro(*args, **kwargs)
  File "/Users/vutheduc/Documents/Projects/PuzzleSoc/Social/Discord/CrypticBot/mycogs/layton/layton.py", line 65, in layton
    if self._current_puzzle is None or not self._current_puzzle['set_answer']:
KeyError: 'set_answer'
[2019-11-15 20:13:11] [ERROR] red: Exception in command 'layton'
Traceback (most recent call last):
  File "/usr/local/lib/python3.7/site-packages/discord/ext/commands/core.py", line 79, in wrapped
    ret = await coro(*args, **kwargs)
  File "/Users/vutheduc/Documents/Projects/PuzzleSoc/Social/Discord/CrypticBot/mycogs/layton/layton.py", line 65, in layton
    if self._current_puzzle is None or not self._current_puzzle['set_answer']:
KeyError: 'set_answer'
[2019-11-15 20:13:15] [ERROR] red: Exception in command 'layton'
Traceback (most recent call last):
  File "/usr/local/lib/python3.7/site-packages/discord/ext/commands/core.py", line 79, in wrapped
    ret = await coro(*args, **kwargs)
  File "/Users/vutheduc/Documents/Projects/PuzzleSoc/Social/Discord/CrypticBot/mycogs/layton/layton.py", line 65, in layton
    if self._current_puzzle is None or not self._current_puzzle['set_answer']:
KeyError: 'set_answer'
[2019-11-15 20:13:17] [ERROR] red: Exception in command 'layton'
Traceback (most recent call last):
  File "/usr/local/lib/python3.7/site-packages/discord/ext/commands/core.py", line 79, in wrapped
    ret = await coro(*args, **kwargs)
  File "/Users/vutheduc/Documents/Projects/PuzzleSoc/Social/Discord/CrypticBot/mycogs/layton/layton.py", line 65, in layton
    if self._current_puzzle is None or not self._current_puzzle['set_answer']:
KeyError: 'set_answer'
[2019-11-15 20:13:19] [ERROR] red: Exception in command 'layton'
Traceback (most recent call last):
  File "/usr/local/lib/python3.7/site-packages/discord/ext/commands/core.py", line 79, in wrapped
    ret = await coro(*args, **kwargs)
  File "/Users/vutheduc/Documents/Projects/PuzzleSoc/Social/Discord/CrypticBot/mycogs/layton/layton.py", line 65, in layton
    if self._current_puzzle is None or not self._current_puzzle['set_answer']:
KeyError: 'set_answer'
[2019-11-15 20:13:29] [ERROR] red: Exception in command 'layton'
Traceback (most recent call last):
  File "/usr/local/lib/python3.7/site-packages/discord/ext/commands/core.py", line 79, in wrapped
    ret = await coro(*args, **kwargs)
  File "/Users/vutheduc/Documents/Projects/PuzzleSoc/Social/Discord/CrypticBot/mycogs/layton/layton.py", line 65, in layton
    if self._current_puzzle is None or not self._current_puzzle['set_answer']:
KeyError: 'set_answer'
[2019-11-15 20:13:33] [ERROR] red: Exception in command 'layton'
Traceback (most recent call last):
  File "/usr/local/lib/python3.7/site-packages/discord/ext/commands/core.py", line 79, in wrapped
    ret = await coro(*args, **kwargs)
  File "/Users/vutheduc/Documents/Projects/PuzzleSoc/Social/Discord/CrypticBot/mycogs/layton/layton.py", line 65, in layton
    if self._current_puzzle is None or not self._current_puzzle['set_answer']:
KeyError: 'set_answer'
[2019-11-15 22:52:11] [INFO] red.main: Keyboard interrupt detected. Quitting...
