[2019-11-10 18:17:55] [ERROR] red: Package loading failed
Traceback (most recent call last):
  File "/usr/local/lib/python3.7/site-packages/redbot/core/core_commands.py", line 106, in _load
    await bot.load_extension(spec)
  File "/usr/local/lib/python3.7/site-packages/redbot/core/bot.py", line 296, in load_extension
    raise discord.ClientException(f"extension {name} does not have a setup function")
discord.errors.ClientException: extension cryptic does not have a setup function
[2019-11-10 18:19:17] [ERROR] red: Package loading failed
Traceback (most recent call last):
  File "/usr/local/lib/python3.7/site-packages/redbot/core/core_commands.py", line 106, in _load
    await bot.load_extension(spec)
  File "/usr/local/lib/python3.7/site-packages/redbot/core/bot.py", line 296, in load_extension
    raise discord.ClientException(f"extension {name} does not have a setup function")
discord.errors.ClientException: extension cryptic does not have a setup function
[2019-11-10 18:21:20] [ERROR] red: Package loading failed
Traceback (most recent call last):
  File "/usr/local/lib/python3.7/site-packages/redbot/core/core_commands.py", line 106, in _load
    await bot.load_extension(spec)
  File "/usr/local/lib/python3.7/site-packages/redbot/core/bot.py", line 296, in load_extension
    raise discord.ClientException(f"extension {name} does not have a setup function")
discord.errors.ClientException: extension cryptic does not have a setup function
[2019-11-10 18:23:41] [INFO] red.main: Keyboard interrupt detected. Quitting...
[2019-11-10 18:24:43] [ERROR] red: Package loading failed
Traceback (most recent call last):
  File "/usr/local/lib/python3.7/site-packages/redbot/core/core_commands.py", line 106, in _load
    await bot.load_extension(spec)
  File "/usr/local/lib/python3.7/site-packages/redbot/core/bot.py", line 296, in load_extension
    raise discord.ClientException(f"extension {name} does not have a setup function")
discord.errors.ClientException: extension cryptic does not have a setup function
[2019-11-10 18:29:19] [ERROR] red: Package loading failed
Traceback (most recent call last):
  File "/usr/local/lib/python3.7/site-packages/redbot/core/core_commands.py", line 106, in _load
    await bot.load_extension(spec)
  File "/usr/local/lib/python3.7/site-packages/redbot/core/bot.py", line 296, in load_extension
    raise discord.ClientException(f"extension {name} does not have a setup function")
discord.errors.ClientException: extension cryptic does not have a setup function
[2019-11-10 18:33:04] [ERROR] red: Package loading failed
Traceback (most recent call last):
  File "/usr/local/lib/python3.7/site-packages/redbot/core/core_commands.py", line 105, in _load
    self._cleanup_and_refresh_modules(spec.name)
  File "/usr/local/lib/python3.7/site-packages/redbot/core/core_commands.py", line 146, in _cleanup_and_refresh_modules
    maybe_reload(m)
  File "/usr/local/lib/python3.7/site-packages/redbot/core/core_commands.py", line 141, in maybe_reload
    importlib._bootstrap._exec(lib.__spec__, lib)
  File "<frozen importlib._bootstrap>", line 630, in _exec
  File "<frozen importlib._bootstrap_external>", line 724, in exec_module
  File "<frozen importlib._bootstrap_external>", line 859, in get_code
  File "<frozen importlib._bootstrap_external>", line 916, in get_data
FileNotFoundError: [Errno 2] No such file or directory: '/Users/vutheduc/Documents/Projects/PuzzleSoc/Social/Discord/CrypticBot/cogs/cryptic/cryptic.py'
[2019-11-10 18:33:39] [ERROR] red: Package loading failed
Traceback (most recent call last):
  File "/usr/local/lib/python3.7/site-packages/redbot/core/core_commands.py", line 105, in _load
    self._cleanup_and_refresh_modules(spec.name)
  File "/usr/local/lib/python3.7/site-packages/redbot/core/core_commands.py", line 146, in _cleanup_and_refresh_modules
    maybe_reload(m)
  File "/usr/local/lib/python3.7/site-packages/redbot/core/core_commands.py", line 141, in maybe_reload
    importlib._bootstrap._exec(lib.__spec__, lib)
  File "<frozen importlib._bootstrap>", line 630, in _exec
  File "<frozen importlib._bootstrap_external>", line 724, in exec_module
  File "<frozen importlib._bootstrap_external>", line 859, in get_code
  File "<frozen importlib._bootstrap_external>", line 916, in get_data
FileNotFoundError: [Errno 2] No such file or directory: '/Users/vutheduc/Documents/Projects/PuzzleSoc/Social/Discord/CrypticBot/cogs/cryptic/cryptic.py'
[2019-11-10 18:35:02] [ERROR] red: Package loading failed
Traceback (most recent call last):
  File "/usr/local/lib/python3.7/site-packages/redbot/core/core_commands.py", line 105, in _load
    self._cleanup_and_refresh_modules(spec.name)
  File "/usr/local/lib/python3.7/site-packages/redbot/core/core_commands.py", line 146, in _cleanup_and_refresh_modules
    maybe_reload(m)
  File "/usr/local/lib/python3.7/site-packages/redbot/core/core_commands.py", line 141, in maybe_reload
    importlib._bootstrap._exec(lib.__spec__, lib)
  File "<frozen importlib._bootstrap>", line 630, in _exec
  File "<frozen importlib._bootstrap_external>", line 724, in exec_module
  File "<frozen importlib._bootstrap_external>", line 859, in get_code
  File "<frozen importlib._bootstrap_external>", line 916, in get_data
FileNotFoundError: [Errno 2] No such file or directory: '/Users/vutheduc/Documents/Projects/PuzzleSoc/Social/Discord/CrypticBot/cogs/cryptic/cryptic.py'
[2019-11-10 18:35:30] [ERROR] red: Package loading failed
Traceback (most recent call last):
  File "/usr/local/lib/python3.7/site-packages/redbot/core/core_commands.py", line 106, in _load
    await bot.load_extension(spec)
  File "/usr/local/lib/python3.7/site-packages/redbot/core/bot.py", line 296, in load_extension
    raise discord.ClientException(f"extension {name} does not have a setup function")
discord.errors.ClientException: extension cryptic does not have a setup function
[2019-11-10 18:51:59] [ERROR] red: Package loading failed
Traceback (most recent call last):
  File "/usr/local/lib/python3.7/site-packages/redbot/core/core_commands.py", line 106, in _load
    await bot.load_extension(spec)
  File "/usr/local/lib/python3.7/site-packages/redbot/core/bot.py", line 296, in load_extension
    raise discord.ClientException(f"extension {name} does not have a setup function")
discord.errors.ClientException: extension cryptic does not have a setup function
[2019-11-10 19:05:03] [ERROR] red: Package loading failed
Traceback (most recent call last):
  File "/usr/local/lib/python3.7/site-packages/redbot/core/core_commands.py", line 106, in _load
    await bot.load_extension(spec)
  File "/usr/local/lib/python3.7/site-packages/redbot/core/bot.py", line 293, in load_extension
    lib = spec.loader.load_module()
  File "<frozen importlib._bootstrap_external>", line 407, in _check_name_wrapper
  File "<frozen importlib._bootstrap_external>", line 907, in load_module
  File "<frozen importlib._bootstrap_external>", line 732, in load_module
  File "<frozen importlib._bootstrap>", line 265, in _load_module_shim
  File "<frozen importlib._bootstrap>", line 696, in _load
  File "<frozen importlib._bootstrap>", line 677, in _load_unlocked
  File "<frozen importlib._bootstrap_external>", line 728, in exec_module
  File "<frozen importlib._bootstrap>", line 219, in _call_with_frames_removed
  File "/Users/vutheduc/Documents/Projects/PuzzleSoc/Social/Discord/CrypticBot/mycogs/aikaterna-cogs/dictionary/__init__.py", line 1, in <module>
    from .dictionary import Dictionary
  File "/Users/vutheduc/Documents/Projects/PuzzleSoc/Social/Discord/CrypticBot/mycogs/aikaterna-cogs/dictionary/dictionary.py", line 2, in <module>
    from bs4 import BeautifulSoup
ModuleNotFoundError: No module named 'bs4'
[2019-11-11 10:15:38] [INFO] red.main: Keyboard interrupt detected. Quitting...
[2019-11-11 12:10:27] [INFO] red.main: Keyboard interrupt detected. Quitting...
[2019-11-11 19:31:13] [ERROR] red: Failed to load package cryptic
Traceback (most recent call last):
  File "C:\Users\cemalk\AppData\Roaming\Python\Python37\site-packages\redbot\core\events.py", line 71, in on_ready
    await bot.load_extension(spec)
  File "C:\Users\cemalk\AppData\Roaming\Python\Python37\site-packages\redbot\core\bot.py", line 289, in load_extension
    name = spec.name.split(".")[-1]
AttributeError: 'NoneType' object has no attribute 'name'
[2019-11-11 19:31:13] [ERROR] red: Failed to load package werewolf
Traceback (most recent call last):
  File "C:\Users\cemalk\AppData\Roaming\Python\Python37\site-packages\redbot\core\events.py", line 71, in on_ready
    await bot.load_extension(spec)
  File "C:\Users\cemalk\AppData\Roaming\Python\Python37\site-packages\redbot\core\bot.py", line 289, in load_extension
    name = spec.name.split(".")[-1]
AttributeError: 'NoneType' object has no attribute 'name'
[2019-11-13 11:32:04] [CRITICAL] red.main: This token doesn't seem to be valid.
[2019-11-13 15:09:59] [CRITICAL] red.main: Fatal exception
Traceback (most recent call last):
  File "/usr/local/lib/python3.7/site-packages/discord/gateway.py", line 468, in poll_event
    msg = await self.recv()
  File "/usr/local/lib/python3.7/site-packages/websockets/protocol.py", line 350, in recv
    yield from self.ensure_open()
  File "/usr/local/lib/python3.7/site-packages/websockets/protocol.py", line 512, in ensure_open
    self.close_code, self.close_reason) from self.transfer_data_exc
websockets.exceptions.ConnectionClosed: WebSocket connection is closed: code = 4004 (private use), reason = Authentication failed.

The above exception was the direct cause of the following exception:

Traceback (most recent call last):
  File "/usr/local/lib/python3.7/site-packages/redbot/__main__.py", line 150, in main
    loop.run_until_complete(red.start(token, bot=True))
  File "uvloop/loop.pyx", line 1417, in uvloop.loop.Loop.run_until_complete
  File "/usr/local/lib/python3.7/site-packages/discord/client.py", line 543, in start
    await self.connect(reconnect=reconnect)
  File "/usr/local/lib/python3.7/site-packages/discord/client.py", line 457, in connect
    await self._connect()
  File "/usr/local/lib/python3.7/site-packages/discord/shard.py", line 274, in _connect
    f.result()
  File "/usr/local/lib/python3.7/site-packages/discord/shard.py", line 78, in poll
    await self.ws.poll_event()
  File "/usr/local/lib/python3.7/site-packages/discord/gateway.py", line 476, in poll_event
    raise ConnectionClosed(exc, shard_id=self.shard_id) from exc
discord.errors.ConnectionClosed: WebSocket connection is closed: code = 4004 (private use), reason = Authentication failed.
[2019-11-13 15:10:25] [CRITICAL] red.main: This token doesn't seem to be valid.
[2019-11-13 15:11:31] [CRITICAL] red.main: This token doesn't seem to be valid.
[2019-11-13 22:09:07] [ERROR] red: Package loading failed
Traceback (most recent call last):
  File "/usr/local/lib/python3.7/site-packages/redbot/core/core_commands.py", line 106, in _load
    await bot.load_extension(spec)
  File "/usr/local/lib/python3.7/site-packages/redbot/core/bot.py", line 293, in load_extension
    lib = spec.loader.load_module()
  File "<frozen importlib._bootstrap_external>", line 407, in _check_name_wrapper
  File "<frozen importlib._bootstrap_external>", line 907, in load_module
  File "<frozen importlib._bootstrap_external>", line 732, in load_module
  File "<frozen importlib._bootstrap>", line 265, in _load_module_shim
  File "<frozen importlib._bootstrap>", line 696, in _load
  File "<frozen importlib._bootstrap>", line 677, in _load_unlocked
  File "<frozen importlib._bootstrap_external>", line 728, in exec_module
  File "<frozen importlib._bootstrap>", line 219, in _call_with_frames_removed
  File "/Users/vutheduc/Documents/Projects/PuzzleSoc/Social/Discord/CrypticBot/mycogs/cryptic/__init__.py", line 1, in <module>
    from .cryptic import Cryptic
  File "/Users/vutheduc/Documents/Projects/PuzzleSoc/Social/Discord/CrypticBot/mycogs/cryptic/cryptic.py", line 13, in <module>
    class Cryptic(commands.Cog):
  File "/Users/vutheduc/Documents/Projects/PuzzleSoc/Social/Discord/CrypticBot/mycogs/cryptic/cryptic.py", line 92, in Cryptic
    @cryptic.command(name="help")
AttributeError: 'Command' object has no attribute 'command'
[2019-11-13 22:09:39] [ERROR] red: Package loading failed
Traceback (most recent call last):
  File "/usr/local/lib/python3.7/site-packages/redbot/core/core_commands.py", line 106, in _load
    await bot.load_extension(spec)
  File "/usr/local/lib/python3.7/site-packages/redbot/core/bot.py", line 293, in load_extension
    lib = spec.loader.load_module()
  File "<frozen importlib._bootstrap_external>", line 407, in _check_name_wrapper
  File "<frozen importlib._bootstrap_external>", line 907, in load_module
  File "<frozen importlib._bootstrap_external>", line 732, in load_module
  File "<frozen importlib._bootstrap>", line 265, in _load_module_shim
  File "<frozen importlib._bootstrap>", line 696, in _load
  File "<frozen importlib._bootstrap>", line 677, in _load_unlocked
  File "<frozen importlib._bootstrap_external>", line 728, in exec_module
  File "<frozen importlib._bootstrap>", line 219, in _call_with_frames_removed
  File "/Users/vutheduc/Documents/Projects/PuzzleSoc/Social/Discord/CrypticBot/mycogs/cryptic/__init__.py", line 1, in <module>
    from .cryptic import Cryptic
  File "/Users/vutheduc/Documents/Projects/PuzzleSoc/Social/Discord/CrypticBot/mycogs/cryptic/cryptic.py", line 13, in <module>
    class Cryptic(commands.Cog):
  File "/Users/vutheduc/Documents/Projects/PuzzleSoc/Social/Discord/CrypticBot/mycogs/cryptic/cryptic.py", line 109, in Cryptic
    @checks.mod_or_permissions(administrator=True)
NameError: name 'checks' is not defined
[2019-11-13 22:10:31] [ERROR] red: Package loading failed
Traceback (most recent call last):
  File "/usr/local/lib/python3.7/site-packages/redbot/core/core_commands.py", line 106, in _load
    await bot.load_extension(spec)
  File "/usr/local/lib/python3.7/site-packages/redbot/core/bot.py", line 302, in load_extension
    lib.setup(self)
  File "/Users/vutheduc/Documents/Projects/PuzzleSoc/Social/Discord/CrypticBot/mycogs/cryptic/__init__.py", line 4, in setup
    bot.add_cog(Cryptic())
  File "/Users/vutheduc/Documents/Projects/PuzzleSoc/Social/Discord/CrypticBot/mycogs/cryptic/cryptic.py", line 17, in __init__
    self._all_clues = self._load_clues()
  File "/Users/vutheduc/Documents/Projects/PuzzleSoc/Social/Discord/CrypticBot/mycogs/cryptic/cryptic.py", line 21, in _load_clues
    with open('data/cryptics.yaml', 'r') as f:
FileNotFoundError: [Errno 2] No such file or directory: 'data/cryptics.yaml'
[2019-11-13 22:10:57] [ERROR] red: Package loading failed
Traceback (most recent call last):
  File "/usr/local/lib/python3.7/site-packages/redbot/core/core_commands.py", line 106, in _load
    await bot.load_extension(spec)
  File "/usr/local/lib/python3.7/site-packages/redbot/core/bot.py", line 302, in load_extension
    lib.setup(self)
  File "/Users/vutheduc/Documents/Projects/PuzzleSoc/Social/Discord/CrypticBot/mycogs/cryptic/__init__.py", line 4, in setup
    bot.add_cog(Cryptic())
  File "/Users/vutheduc/Documents/Projects/PuzzleSoc/Social/Discord/CrypticBot/mycogs/cryptic/cryptic.py", line 17, in __init__
    self._all_clues = self._load_clues()
  File "/Users/vutheduc/Documents/Projects/PuzzleSoc/Social/Discord/CrypticBot/mycogs/cryptic/cryptic.py", line 21, in _load_clues
    with open('./data/cryptics.yaml', 'r') as f:
FileNotFoundError: [Errno 2] No such file or directory: './data/cryptics.yaml'
[2019-11-13 22:16:40] [ERROR] red: Package loading failed
Traceback (most recent call last):
  File "/usr/local/lib/python3.7/site-packages/redbot/core/core_commands.py", line 106, in _load
    await bot.load_extension(spec)
  File "/usr/local/lib/python3.7/site-packages/redbot/core/bot.py", line 293, in load_extension
    lib = spec.loader.load_module()
  File "<frozen importlib._bootstrap_external>", line 407, in _check_name_wrapper
  File "<frozen importlib._bootstrap_external>", line 907, in load_module
  File "<frozen importlib._bootstrap_external>", line 732, in load_module
  File "<frozen importlib._bootstrap>", line 265, in _load_module_shim
  File "<frozen importlib._bootstrap>", line 696, in _load
  File "<frozen importlib._bootstrap>", line 677, in _load_unlocked
  File "<frozen importlib._bootstrap_external>", line 728, in exec_module
  File "<frozen importlib._bootstrap>", line 219, in _call_with_frames_removed
  File "/Users/vutheduc/Documents/Projects/PuzzleSoc/Social/Discord/CrypticBot/mycogs/cryptic/__init__.py", line 1, in <module>
    from .cryptic import Cryptic
  File "/Users/vutheduc/Documents/Projects/PuzzleSoc/Social/Discord/CrypticBot/mycogs/cryptic/cryptic.py", line 14, in <module>
    class Cryptic(commands.Cog):
  File "/Users/vutheduc/Documents/Projects/PuzzleSoc/Social/Discord/CrypticBot/mycogs/cryptic/cryptic.py", line 22, in Cryptic
    def _load_clues(self) -> List[pathlib.Path]:
NameError: name 'List' is not defined
[2019-11-13 22:29:14] [ERROR] red: Package loading failed
Traceback (most recent call last):
  File "/usr/local/lib/python3.7/site-packages/redbot/core/core_commands.py", line 106, in _load
    await bot.load_extension(spec)
  File "/usr/local/lib/python3.7/site-packages/redbot/core/bot.py", line 302, in load_extension
    lib.setup(self)
  File "/Users/vutheduc/Documents/Projects/PuzzleSoc/Social/Discord/CrypticBot/mycogs/cryptic/__init__.py", line 4, in setup
    bot.add_cog(Cryptic())
  File "/Users/vutheduc/Documents/Projects/PuzzleSoc/Social/Discord/CrypticBot/mycogs/cryptic/cryptic.py", line 19, in __init__
    self._all_clues = self._load_clues()
  File "/Users/vutheduc/Documents/Projects/PuzzleSoc/Social/Discord/CrypticBot/mycogs/cryptic/cryptic.py", line 24, in _load_clues
    with open('cryptics.yaml', 'r', encoding='utf-8') as f:
FileNotFoundError: [Errno 2] No such file or directory: 'cryptics.yaml'
[2019-11-13 22:34:00] [ERROR] red: Package loading failed
Traceback (most recent call last):
  File "/usr/local/lib/python3.7/site-packages/redbot/core/core_commands.py", line 106, in _load
    await bot.load_extension(spec)
  File "/usr/local/lib/python3.7/site-packages/redbot/core/bot.py", line 302, in load_extension
    lib.setup(self)
  File "/Users/vutheduc/Documents/Projects/PuzzleSoc/Social/Discord/CrypticBot/mycogs/cryptic/__init__.py", line 4, in setup
    bot.add_cog(Cryptic())
  File "/Users/vutheduc/Documents/Projects/PuzzleSoc/Social/Discord/CrypticBot/mycogs/cryptic/cryptic.py", line 19, in __init__
    self._all_clues = self._load_clues()
  File "/Users/vutheduc/Documents/Projects/PuzzleSoc/Social/Discord/CrypticBot/mycogs/cryptic/cryptic.py", line 25, in _load_clues
    with open(path + 'cryptics.yaml', 'r', encoding='utf-8') as f:
TypeError: unsupported operand type(s) for +: 'PosixPath' and 'str'
[2019-11-13 22:34:38] [ERROR] red: Exception in command 'cryptic'
Traceback (most recent call last):
  File "/usr/local/lib/python3.7/site-packages/discord/ext/commands/core.py", line 79, in wrapped
    ret = await coro(*args, **kwargs)
  File "/Users/vutheduc/Documents/Projects/PuzzleSoc/Social/Discord/CrypticBot/mycogs/cryptic/cryptic.py", line 41, in cryptic
    ans = self._all_clues[clue]
KeyError: None
[2019-11-13 22:35:54] [ERROR] red: Exception in command 'cryptic'
Traceback (most recent call last):
  File "/usr/local/lib/python3.7/site-packages/discord/ext/commands/core.py", line 79, in wrapped
    ret = await coro(*args, **kwargs)
  File "/Users/vutheduc/Documents/Projects/PuzzleSoc/Social/Discord/CrypticBot/mycogs/cryptic/cryptic.py", line 41, in cryptic
    clue = random.choice(self._all_clues.keys())
KeyError: None
[2019-11-13 22:36:12] [ERROR] red: Exception in command 'cryptic'
Traceback (most recent call last):
  File "/usr/local/lib/python3.7/site-packages/discord/ext/commands/core.py", line 79, in wrapped
    ret = await coro(*args, **kwargs)
  File "/Users/vutheduc/Documents/Projects/PuzzleSoc/Social/Discord/CrypticBot/mycogs/cryptic/cryptic.py", line 42, in cryptic
    ans = self._all_clues[clue]
KeyError: None
[2019-11-13 22:36:46] [ERROR] red: Exception in command 'cryptic'
Traceback (most recent call last):
  File "/usr/local/lib/python3.7/site-packages/discord/ext/commands/core.py", line 79, in wrapped
    ret = await coro(*args, **kwargs)
  File "/Users/vutheduc/Documents/Projects/PuzzleSoc/Social/Discord/CrypticBot/mycogs/cryptic/cryptic.py", line 42, in cryptic
    ans = self._all_clues[clue]
KeyError: None
[2019-11-13 22:36:53] [ERROR] red: Exception in command 'cryptic'
Traceback (most recent call last):
  File "/usr/local/lib/python3.7/site-packages/discord/ext/commands/core.py", line 79, in wrapped
    ret = await coro(*args, **kwargs)
  File "/Users/vutheduc/Documents/Projects/PuzzleSoc/Social/Discord/CrypticBot/mycogs/cryptic/cryptic.py", line 41, in cryptic
    clue = random.choice(self._all_clues.keys())
  File "/usr/local/Cellar/python/3.7.0/Frameworks/Python.framework/Versions/3.7/lib/python3.7/random.py", line 262, in choice
    return seq[i]
TypeError: 'dict_keys' object does not support indexing
[2019-11-13 22:37:15] [ERROR] red: Exception in command 'cryptic'
Traceback (most recent call last):
  File "/usr/local/lib/python3.7/site-packages/discord/ext/commands/core.py", line 79, in wrapped
    ret = await coro(*args, **kwargs)
  File "/Users/vutheduc/Documents/Projects/PuzzleSoc/Social/Discord/CrypticBot/mycogs/cryptic/cryptic.py", line 54, in cryptic
    continue_ = await self.wait_for_answer(ans, 0)
  File "/Users/vutheduc/Documents/Projects/PuzzleSoc/Social/Discord/CrypticBot/mycogs/cryptic/cryptic.py", line 78, in wait_for_answer
    message = await self.ctx.bot.wait_for(
AttributeError: 'Cryptic' object has no attribute 'ctx'
[2019-11-13 22:38:37] [ERROR] red: Exception in command 'cryptic'
Traceback (most recent call last):
  File "/usr/local/lib/python3.7/site-packages/discord/ext/commands/core.py", line 79, in wrapped
    ret = await coro(*args, **kwargs)
  File "/Users/vutheduc/Documents/Projects/PuzzleSoc/Social/Discord/CrypticBot/mycogs/cryptic/cryptic.py", line 55, in cryptic
    continue_ = await self.wait_for_answer(ans, 0)
  File "/Users/vutheduc/Documents/Projects/PuzzleSoc/Social/Discord/CrypticBot/mycogs/cryptic/cryptic.py", line 80, in wait_for_answer
    "message", check=self.check_answer(answer), timeout=delay
  File "/Users/vutheduc/Documents/Projects/PuzzleSoc/Social/Discord/CrypticBot/mycogs/cryptic/cryptic.py", line 96, in check_answer
    def _pred(message: discord.Message):
NameError: name 'discord' is not defined
[2019-11-13 22:39:33] [INFO] red.main: Keyboard interrupt detected. Quitting...
[2019-11-13 22:48:12] [ERROR] red: Package loading failed
Traceback (most recent call last):
  File "/usr/local/lib/python3.7/site-packages/redbot/core/core_commands.py", line 106, in _load
    await bot.load_extension(spec)
  File "/usr/local/lib/python3.7/site-packages/redbot/core/bot.py", line 293, in load_extension
    lib = spec.loader.load_module()
  File "<frozen importlib._bootstrap_external>", line 407, in _check_name_wrapper
  File "<frozen importlib._bootstrap_external>", line 907, in load_module
  File "<frozen importlib._bootstrap_external>", line 732, in load_module
  File "<frozen importlib._bootstrap>", line 265, in _load_module_shim
  File "<frozen importlib._bootstrap>", line 696, in _load
  File "<frozen importlib._bootstrap>", line 677, in _load_unlocked
  File "<frozen importlib._bootstrap_external>", line 728, in exec_module
  File "<frozen importlib._bootstrap>", line 219, in _call_with_frames_removed
  File "/Users/vutheduc/Documents/Projects/PuzzleSoc/Social/Discord/CrypticBot/mycogs/cryptic/__init__.py", line 1, in <module>
    from .cryptic import Cryptic
  File "/Users/vutheduc/Documents/Projects/PuzzleSoc/Social/Discord/CrypticBot/mycogs/cryptic/cryptic.py", line 26, in <module>
    class Cryptic(commands.Cog):
  File "/Users/vutheduc/Documents/Projects/PuzzleSoc/Social/Discord/CrypticBot/mycogs/cryptic/cryptic.py", line 115, in Cryptic
    @cryptic.command(name="help")
AttributeError: 'Command' object has no attribute 'command'
[2019-11-13 22:55:00] [ERROR] red: Exception in command 'help'
Traceback (most recent call last):
  File "/usr/local/lib/python3.7/site-packages/redbot/core/commands/help.py", line 560, in send_pages
    await destination.send(page)
  File "/usr/local/lib/python3.7/site-packages/redbot/core/commands/context.py", line 64, in send
    return await super().send(content=content, **kwargs)
  File "/usr/local/lib/python3.7/site-packages/discord/abc.py", line 823, in send
    data = await state.http.send_message(channel.id, content, tts=tts, embed=embed, nonce=nonce)
  File "/usr/local/lib/python3.7/site-packages/discord/http.py", line 218, in request
    raise Forbidden(r, data)
discord.errors.Forbidden: 403 FORBIDDEN (error code: 50013): Missing Permissions

During handling of the above exception, another exception occurred:

Traceback (most recent call last):
  File "/usr/local/lib/python3.7/site-packages/discord/ext/commands/core.py", line 79, in wrapped
    ret = await coro(*args, **kwargs)
  File "/usr/local/lib/python3.7/site-packages/redbot/core/commands/help.py", line 586, in red_help
    await ctx.bot.send_help_for(ctx, thing_to_get_help_for)
  File "/usr/local/lib/python3.7/site-packages/redbot/core/bot.py", line 176, in send_help_for
    return await self._help_formatter.send_help(ctx, help_for)
  File "/usr/local/lib/python3.7/site-packages/redbot/core/commands/help.py", line 88, in send_help
    await self.format_bot_help(ctx)
  File "/usr/local/lib/python3.7/site-packages/redbot/core/commands/help.py", line 427, in format_bot_help
    await self.send_pages(ctx, pages, embed=False)
  File "/usr/local/lib/python3.7/site-packages/redbot/core/commands/help.py", line 564, in send_pages
    "I couldn't send the help message to you in DM. "
  File "/usr/local/lib/python3.7/site-packages/redbot/core/commands/context.py", line 64, in send
    return await super().send(content=content, **kwargs)
  File "/usr/local/lib/python3.7/site-packages/discord/abc.py", line 823, in send
    data = await state.http.send_message(channel.id, content, tts=tts, embed=embed, nonce=nonce)
  File "/usr/local/lib/python3.7/site-packages/discord/http.py", line 218, in request
    raise Forbidden(r, data)
discord.errors.Forbidden: 403 FORBIDDEN (error code: 50013): Missing Permissions
[2019-11-13 22:58:02] [ERROR] red: Exception in command 'cryptic'
Traceback (most recent call last):
  File "/usr/local/lib/python3.7/site-packages/discord/ext/commands/core.py", line 79, in wrapped
    ret = await coro(*args, **kwargs)
  File "/Users/vutheduc/Documents/Projects/PuzzleSoc/Social/Discord/CrypticBot/mycogs/cryptic/cryptic.py", line 67, in cryptic
    continue_ = await self.wait_for_answer(ans, 500)
  File "/Users/vutheduc/Documents/Projects/PuzzleSoc/Social/Discord/CrypticBot/mycogs/cryptic/cryptic.py", line 102, in wait_for_answer
    bold(f'{clue} ({ans_len})') + '\n\n'
  File "/usr/local/lib/python3.7/site-packages/redbot/core/commands/context.py", line 64, in send
    return await super().send(content=content, **kwargs)
  File "/usr/local/lib/python3.7/site-packages/discord/abc.py", line 823, in send
    data = await state.http.send_message(channel.id, content, tts=tts, embed=embed, nonce=nonce)
  File "/usr/local/lib/python3.7/site-packages/discord/http.py", line 220, in request
    raise NotFound(r, data)
discord.errors.NotFound: 404 NOT FOUND (error code: 10003): Unknown Channel
[2019-11-13 23:05:29] [ERROR] red: Exception in command 'help'
Traceback (most recent call last):
  File "/usr/local/lib/python3.7/site-packages/redbot/core/commands/help.py", line 560, in send_pages
    await destination.send(page)
  File "/usr/local/lib/python3.7/site-packages/redbot/core/commands/context.py", line 64, in send
    return await super().send(content=content, **kwargs)
  File "/usr/local/lib/python3.7/site-packages/discord/abc.py", line 823, in send
    data = await state.http.send_message(channel.id, content, tts=tts, embed=embed, nonce=nonce)
  File "/usr/local/lib/python3.7/site-packages/discord/http.py", line 218, in request
    raise Forbidden(r, data)
discord.errors.Forbidden: 403 FORBIDDEN (error code: 50013): Missing Permissions

During handling of the above exception, another exception occurred:

Traceback (most recent call last):
  File "/usr/local/lib/python3.7/site-packages/discord/ext/commands/core.py", line 79, in wrapped
    ret = await coro(*args, **kwargs)
  File "/usr/local/lib/python3.7/site-packages/redbot/core/commands/help.py", line 586, in red_help
    await ctx.bot.send_help_for(ctx, thing_to_get_help_for)
  File "/usr/local/lib/python3.7/site-packages/redbot/core/bot.py", line 176, in send_help_for
    return await self._help_formatter.send_help(ctx, help_for)
  File "/usr/local/lib/python3.7/site-packages/redbot/core/commands/help.py", line 88, in send_help
    await self.format_bot_help(ctx)
  File "/usr/local/lib/python3.7/site-packages/redbot/core/commands/help.py", line 427, in format_bot_help
    await self.send_pages(ctx, pages, embed=False)
  File "/usr/local/lib/python3.7/site-packages/redbot/core/commands/help.py", line 564, in send_pages
    "I couldn't send the help message to you in DM. "
  File "/usr/local/lib/python3.7/site-packages/redbot/core/commands/context.py", line 64, in send
    return await super().send(content=content, **kwargs)
  File "/usr/local/lib/python3.7/site-packages/discord/abc.py", line 823, in send
    data = await state.http.send_message(channel.id, content, tts=tts, embed=embed, nonce=nonce)
  File "/usr/local/lib/python3.7/site-packages/discord/http.py", line 218, in request
    raise Forbidden(r, data)
discord.errors.Forbidden: 403 FORBIDDEN (error code: 50013): Missing Permissions
[2019-11-13 23:05:46] [ERROR] red: Exception in command 'trivia'
Traceback (most recent call last):
  File "/usr/local/lib/python3.7/site-packages/redbot/core/commands/help.py", line 560, in send_pages
    await destination.send(page)
  File "/usr/local/lib/python3.7/site-packages/redbot/core/commands/context.py", line 64, in send
    return await super().send(content=content, **kwargs)
  File "/usr/local/lib/python3.7/site-packages/discord/abc.py", line 823, in send
    data = await state.http.send_message(channel.id, content, tts=tts, embed=embed, nonce=nonce)
  File "/usr/local/lib/python3.7/site-packages/discord/http.py", line 218, in request
    raise Forbidden(r, data)
discord.errors.Forbidden: 403 FORBIDDEN (error code: 50013): Missing Permissions

During handling of the above exception, another exception occurred:

Traceback (most recent call last):
  File "/usr/local/lib/python3.7/site-packages/discord/ext/commands/core.py", line 79, in wrapped
    ret = await coro(*args, **kwargs)
  File "/Users/vutheduc/Documents/Projects/PuzzleSoc/Social/Discord/CrypticBot/mycogs/trivia2/trivia.py", line 182, in trivia
    await ctx.send_help()
  File "/usr/local/lib/python3.7/site-packages/redbot/core/commands/context.py", line 71, in send_help
    await self.bot.send_help_for(self, command)
  File "/usr/local/lib/python3.7/site-packages/redbot/core/bot.py", line 176, in send_help_for
    return await self._help_formatter.send_help(ctx, help_for)
  File "/usr/local/lib/python3.7/site-packages/redbot/core/commands/help.py", line 106, in send_help
    await self.format_command_help(ctx, help_for)
  File "/usr/local/lib/python3.7/site-packages/redbot/core/commands/help.py", line 233, in format_command_help
    await self.send_pages(ctx, pages, embed=False)
  File "/usr/local/lib/python3.7/site-packages/redbot/core/commands/help.py", line 564, in send_pages
    "I couldn't send the help message to you in DM. "
  File "/usr/local/lib/python3.7/site-packages/redbot/core/commands/context.py", line 64, in send
    return await super().send(content=content, **kwargs)
  File "/usr/local/lib/python3.7/site-packages/discord/abc.py", line 823, in send
    data = await state.http.send_message(channel.id, content, tts=tts, embed=embed, nonce=nonce)
  File "/usr/local/lib/python3.7/site-packages/discord/http.py", line 218, in request
    raise Forbidden(r, data)
discord.errors.Forbidden: 403 FORBIDDEN (error code: 50013): Missing Permissions
[2019-11-13 23:15:48] [ERROR] red: Exception in command 'cryptic'
Traceback (most recent call last):
  File "/usr/local/lib/python3.7/site-packages/discord/ext/commands/core.py", line 79, in wrapped
    ret = await coro(*args, **kwargs)
  File "/Users/vutheduc/Documents/Projects/PuzzleSoc/Social/Discord/CrypticBot/mycogs/cryptic/cryptic.py", line 57, in cryptic
    ans_len = ', '.join([len(a) for a in ans.split()])
TypeError: sequence item 0: expected str instance, int found
[2019-11-13 23:21:20] [ERROR] red: Exception in command 'cryptic'
Traceback (most recent call last):
  File "/usr/local/lib/python3.7/site-packages/discord/ext/commands/core.py", line 79, in wrapped
    ret = await coro(*args, **kwargs)
  File "/Users/vutheduc/Documents/Projects/PuzzleSoc/Social/Discord/CrypticBot/mycogs/cryptic/cryptic.py", line 63, in cryptic
    await ctx.send(text + "\n\n" + bold(f'{clue} ({ans_len})'))
UnboundLocalError: local variable 'text' referenced before assignment
[2019-11-13 23:22:26] [ERROR] red: Exception in command 'help'
Traceback (most recent call last):
  File "/usr/local/lib/python3.7/site-packages/redbot/core/commands/help.py", line 560, in send_pages
    await destination.send(page)
  File "/usr/local/lib/python3.7/site-packages/redbot/core/commands/context.py", line 64, in send
    return await super().send(content=content, **kwargs)
  File "/usr/local/lib/python3.7/site-packages/discord/abc.py", line 823, in send
    data = await state.http.send_message(channel.id, content, tts=tts, embed=embed, nonce=nonce)
  File "/usr/local/lib/python3.7/site-packages/discord/http.py", line 218, in request
    raise Forbidden(r, data)
discord.errors.Forbidden: 403 FORBIDDEN (error code: 50013): Missing Permissions

During handling of the above exception, another exception occurred:

Traceback (most recent call last):
  File "/usr/local/lib/python3.7/site-packages/discord/ext/commands/core.py", line 79, in wrapped
    ret = await coro(*args, **kwargs)
  File "/usr/local/lib/python3.7/site-packages/redbot/core/commands/help.py", line 586, in red_help
    await ctx.bot.send_help_for(ctx, thing_to_get_help_for)
  File "/usr/local/lib/python3.7/site-packages/redbot/core/bot.py", line 176, in send_help_for
    return await self._help_formatter.send_help(ctx, help_for)
  File "/usr/local/lib/python3.7/site-packages/redbot/core/commands/help.py", line 88, in send_help
    await self.format_bot_help(ctx)
  File "/usr/local/lib/python3.7/site-packages/redbot/core/commands/help.py", line 427, in format_bot_help
    await self.send_pages(ctx, pages, embed=False)
  File "/usr/local/lib/python3.7/site-packages/redbot/core/commands/help.py", line 564, in send_pages
    "I couldn't send the help message to you in DM. "
  File "/usr/local/lib/python3.7/site-packages/redbot/core/commands/context.py", line 64, in send
    return await super().send(content=content, **kwargs)
  File "/usr/local/lib/python3.7/site-packages/discord/abc.py", line 823, in send
    data = await state.http.send_message(channel.id, content, tts=tts, embed=embed, nonce=nonce)
  File "/usr/local/lib/python3.7/site-packages/discord/http.py", line 218, in request
    raise Forbidden(r, data)
discord.errors.Forbidden: 403 FORBIDDEN (error code: 50013): Missing Permissions
[2019-11-14 21:08:51] [ERROR] red: Exception in command 'cryptic'
Traceback (most recent call last):
  File "/usr/local/lib/python3.7/site-packages/discord/ext/commands/core.py", line 79, in wrapped
    ret = await coro(*args, **kwargs)
  File "/Users/vutheduc/Documents/Projects/PuzzleSoc/Social/Discord/CrypticBot/mycogs/cryptic/cryptic.py", line 72, in cryptic
    text = random.choice(STARTING_TEXTS)
NameError: name 'STARTING_TEXTS' is not defined
[2019-11-15 19:17:57] [ERROR] red: Package loading failed
Traceback (most recent call last):
  File "/usr/local/lib/python3.7/site-packages/redbot/core/core_commands.py", line 106, in _load
    await bot.load_extension(spec)
  File "/usr/local/lib/python3.7/site-packages/redbot/core/bot.py", line 293, in load_extension
    lib = spec.loader.load_module()
  File "<frozen importlib._bootstrap_external>", line 407, in _check_name_wrapper
  File "<frozen importlib._bootstrap_external>", line 907, in load_module
  File "<frozen importlib._bootstrap_external>", line 732, in load_module
  File "<frozen importlib._bootstrap>", line 265, in _load_module_shim
  File "<frozen importlib._bootstrap>", line 696, in _load
  File "<frozen importlib._bootstrap>", line 677, in _load_unlocked
  File "<frozen importlib._bootstrap_external>", line 728, in exec_module
  File "<frozen importlib._bootstrap>", line 219, in _call_with_frames_removed
  File "/Users/vutheduc/Documents/Projects/PuzzleSoc/Social/Discord/CrypticBot/mycogs/layton/__init__.py", line 1, in <module>
    from .cryptic import Cryptic
ModuleNotFoundError: No module named 'layton.cryptic'
[2019-11-15 19:24:04] [ERROR] red: Package loading failed
Traceback (most recent call last):
  File "/usr/local/lib/python3.7/site-packages/redbot/core/core_commands.py", line 106, in _load
    await bot.load_extension(spec)
  File "/usr/local/lib/python3.7/site-packages/redbot/core/bot.py", line 293, in load_extension
    lib = spec.loader.load_module()
  File "<frozen importlib._bootstrap_external>", line 407, in _check_name_wrapper
  File "<frozen importlib._bootstrap_external>", line 907, in load_module
  File "<frozen importlib._bootstrap_external>", line 732, in load_module
  File "<frozen importlib._bootstrap>", line 265, in _load_module_shim
  File "<frozen importlib._bootstrap>", line 696, in _load
  File "<frozen importlib._bootstrap>", line 677, in _load_unlocked
  File "<frozen importlib._bootstrap_external>", line 728, in exec_module
  File "<frozen importlib._bootstrap>", line 219, in _call_with_frames_removed
  File "/Users/vutheduc/Documents/Projects/PuzzleSoc/Social/Discord/CrypticBot/mycogs/layton/__init__.py", line 1, in <module>
    from .cryptic import Cryptic
ModuleNotFoundError: No module named 'layton.cryptic'
[2019-11-15 19:24:35] [ERROR] red: Exception in command 'layton'
Traceback (most recent call last):
  File "/usr/local/lib/python3.7/site-packages/discord/ext/commands/core.py", line 79, in wrapped
    ret = await coro(*args, **kwargs)
  File "/Users/vutheduc/Documents/Projects/PuzzleSoc/Social/Discord/CrypticBot/mycogs/layton/layton.py", line 63, in layton
    if self._current_puzzle is None and not self._current_puzzle['set_answer']:
TypeError: 'NoneType' object is not subscriptable
[2019-11-15 19:25:15] [ERROR] red: Exception in command 'layton'
Traceback (most recent call last):
  File "/usr/local/lib/python3.7/site-packages/discord/ext/commands/core.py", line 79, in wrapped
    ret = await coro(*args, **kwargs)
  File "/Users/vutheduc/Documents/Projects/PuzzleSoc/Social/Discord/CrypticBot/mycogs/layton/layton.py", line 63, in layton
    if self._current_puzzle is None or not self._current_puzzle['set_answer']:
TypeError: 'NoneType' object is not subscriptable
[2019-11-15 19:28:04] [ERROR] red: Exception in command 'layton'
Traceback (most recent call last):
  File "/usr/local/lib/python3.7/site-packages/discord/ext/commands/core.py", line 79, in wrapped
    ret = await coro(*args, **kwargs)
  File "/Users/vutheduc/Documents/Projects/PuzzleSoc/Social/Discord/CrypticBot/mycogs/layton/layton.py", line 63, in layton
    if self._current_puzzle is None or 'set_answer' in self._current_puzzle:
TypeError: 'NoneType' object is not subscriptable
[2019-11-15 19:29:07] [ERROR] red: Exception in command 'layton'
Traceback (most recent call last):
  File "/usr/local/lib/python3.7/site-packages/discord/ext/commands/core.py", line 79, in wrapped
    ret = await coro(*args, **kwargs)
  File "/Users/vutheduc/Documents/Projects/PuzzleSoc/Social/Discord/CrypticBot/mycogs/layton/layton.py", line 64, in layton
    id_ = random.choice(list(self._puzzles.keys()))
AttributeError: 'NoneType' object has no attribute 'keys'
[2019-11-15 19:50:09] [ERROR] red: Exception in command 'layton'
Traceback (most recent call last):
  File "/usr/local/lib/python3.7/site-packages/discord/ext/commands/core.py", line 79, in wrapped
    ret = await coro(*args, **kwargs)
  File "/Users/vutheduc/Documents/Projects/PuzzleSoc/Social/Discord/CrypticBot/mycogs/layton/layton.py", line 64, in layton
    id_ = random.choice(list(self._puzzles.keys()))
AttributeError: 'NoneType' object has no attribute 'keys'
[2019-11-15 19:50:20] [ERROR] red: Exception in command 'layton'
Traceback (most recent call last):
  File "/usr/local/lib/python3.7/site-packages/discord/ext/commands/core.py", line 79, in wrapped
    ret = await coro(*args, **kwargs)
  File "/Users/vutheduc/Documents/Projects/PuzzleSoc/Social/Discord/CrypticBot/mycogs/layton/layton.py", line 66, in layton
    self._current_puzzle = grab_puzzle(id_)
  File "/Users/vutheduc/Documents/Projects/PuzzleSoc/Social/Discord/CrypticBot/mycogs/layton/layton.py", line 178, in grab_puzzle
    puzzle_soup = BeautifulSoup(
NameError: name 'BeautifulSoup' is not defined
[2019-11-15 19:50:41] [ERROR] red: Exception in command 'layton'
Traceback (most recent call last):
  File "/usr/local/lib/python3.7/site-packages/discord/ext/commands/core.py", line 79, in wrapped
    ret = await coro(*args, **kwargs)
  File "/Users/vutheduc/Documents/Projects/PuzzleSoc/Social/Discord/CrypticBot/mycogs/layton/layton.py", line 66, in layton
    answers = [ans for ans in self._puzzles[id_] if ans != '']
  File "/Users/vutheduc/Documents/Projects/PuzzleSoc/Social/Discord/CrypticBot/mycogs/layton/layton.py", line 178, in grab_puzzle
    puzzle_html = requests.get(puzzle_dict['URL'])
NameError: name 'BeautifulSoup' is not defined
[2019-11-15 19:50:46] [ERROR] red: Exception in command 'layton'
Traceback (most recent call last):
  File "/usr/local/lib/python3.7/site-packages/discord/ext/commands/core.py", line 79, in wrapped
    ret = await coro(*args, **kwargs)
  File "/Users/vutheduc/Documents/Projects/PuzzleSoc/Social/Discord/CrypticBot/mycogs/layton/layton.py", line 66, in layton
    answers = [ans for ans in self._puzzles[id_] if ans != '']
  File "/Users/vutheduc/Documents/Projects/PuzzleSoc/Social/Discord/CrypticBot/mycogs/layton/layton.py", line 184, in grab_puzzle
    puzzle_dict['image'] = image['src']
TypeError: 'NoneType' object is not subscriptable
[2019-11-15 19:52:09] [ERROR] red: Exception in command 'layton'
Traceback (most recent call last):
  File "/usr/local/lib/python3.7/site-packages/discord/ext/commands/core.py", line 79, in wrapped
    ret = await coro(*args, **kwargs)
  File "/Users/vutheduc/Documents/Projects/PuzzleSoc/Social/Discord/CrypticBot/mycogs/layton/layton.py", line 67, in layton
    self._current_puzzle = grab_puzzle(id_)
  File "/Users/vutheduc/Documents/Projects/PuzzleSoc/Social/Discord/CrypticBot/mycogs/layton/layton.py", line 190, in grab_puzzle
    parser.feed(str(puzzle_soup.select("div[data-source='game']")[0]))
NameError: name 'parser' is not defined
[2019-11-15 19:52:57] [ERROR] red: Package loading failed
Traceback (most recent call last):
  File "/usr/local/lib/python3.7/site-packages/redbot/core/core_commands.py", line 106, in _load
    await bot.load_extension(spec)
  File "/usr/local/lib/python3.7/site-packages/redbot/core/bot.py", line 293, in load_extension
    lib = spec.loader.load_module()
  File "<frozen importlib._bootstrap_external>", line 407, in _check_name_wrapper
  File "<frozen importlib._bootstrap_external>", line 907, in load_module
  File "<frozen importlib._bootstrap_external>", line 732, in load_module
  File "<frozen importlib._bootstrap>", line 265, in _load_module_shim
  File "<frozen importlib._bootstrap>", line 696, in _load
  File "<frozen importlib._bootstrap>", line 677, in _load_unlocked
  File "<frozen importlib._bootstrap_external>", line 728, in exec_module
  File "<frozen importlib._bootstrap>", line 219, in _call_with_frames_removed
  File "/Users/vutheduc/Documents/Projects/PuzzleSoc/Social/Discord/CrypticBot/mycogs/layton/__init__.py", line 1, in <module>
    from .layton import Layton
  File "/Users/vutheduc/Documents/Projects/PuzzleSoc/Social/Discord/CrypticBot/mycogs/layton/layton.py", line 171, in <module>
    class MyHTMLParser(HTMLParser):
NameError: name 'HTMLParser' is not defined
[2019-11-15 19:53:16] [ERROR] red: Exception in command 'layton'
Traceback (most recent call last):
  File "/usr/local/lib/python3.7/site-packages/discord/ext/commands/core.py", line 79, in wrapped
    ret = await coro(*args, **kwargs)
  File "/Users/vutheduc/Documents/Projects/PuzzleSoc/Social/Discord/CrypticBot/mycogs/layton/layton.py", line 68, in layton
    self._current_puzzle = grab_puzzle(id_)
  File "/Users/vutheduc/Documents/Projects/PuzzleSoc/Social/Discord/CrypticBot/mycogs/layton/layton.py", line 201, in grab_puzzle
    parser.feed(str(puzzle_soup.select("div[data-source='game']")[0]))
IndexError: list index out of range
[2019-11-15 19:54:09] [ERROR] red: Exception in command 'layton'
Traceback (most recent call last):
  File "/usr/local/lib/python3.7/site-packages/discord/ext/commands/core.py", line 79, in wrapped
    ret = await coro(*args, **kwargs)
  File "/Users/vutheduc/Documents/Projects/PuzzleSoc/Social/Discord/CrypticBot/mycogs/layton/layton.py", line 68, in layton
    self._current_puzzle = grab_puzzle(id_)
  File "/Users/vutheduc/Documents/Projects/PuzzleSoc/Social/Discord/CrypticBot/mycogs/layton/layton.py", line 225, in grab_puzzle
    print(game, number, picarats)
UnboundLocalError: local variable 'game' referenced before assignment
[2019-11-15 19:54:29] [ERROR] red: Exception in command 'layton'
Traceback (most recent call last):
  File "/usr/local/lib/python3.7/site-packages/discord/ext/commands/core.py", line 79, in wrapped
    ret = await coro(*args, **kwargs)
  File "/Users/vutheduc/Documents/Projects/PuzzleSoc/Social/Discord/CrypticBot/mycogs/layton/layton.py", line 68, in layton
    self._current_puzzle = grab_puzzle(id_)
  File "/Users/vutheduc/Documents/Projects/PuzzleSoc/Social/Discord/CrypticBot/mycogs/layton/layton.py", line 225, in grab_puzzle
    puzzle_dict['game'] = game
UnboundLocalError: local variable 'game' referenced before assignment
[2019-11-15 19:55:04] [ERROR] red: Exception in command 'layton'
Traceback (most recent call last):
  File "/usr/local/lib/python3.7/site-packages/discord/ext/commands/core.py", line 79, in wrapped
    ret = await coro(*args, **kwargs)
  File "/Users/vutheduc/Documents/Projects/PuzzleSoc/Social/Discord/CrypticBot/mycogs/layton/layton.py", line 68, in layton
    self._current_puzzle = grab_puzzle(id_)
  File "/Users/vutheduc/Documents/Projects/PuzzleSoc/Social/Discord/CrypticBot/mycogs/layton/layton.py", line 230, in grab_puzzle
    puzzle_span = puzzle_soup.find('span', id='Puzzle').parent.parent
AttributeError: 'NoneType' object has no attribute 'parent'
[2019-11-15 20:09:09] [ERROR] red: Exception in command 'layton'
Traceback (most recent call last):
  File "/usr/local/lib/python3.7/site-packages/discord/ext/commands/core.py", line 79, in wrapped
    ret = await coro(*args, **kwargs)
  File "/Users/vutheduc/Documents/Projects/PuzzleSoc/Social/Discord/CrypticBot/mycogs/layton/layton.py", line 76, in layton
    continue_ = await self.wait_for_answer(answers, 1, 900)
  File "/Users/vutheduc/Documents/Projects/PuzzleSoc/Social/Discord/CrypticBot/mycogs/layton/layton.py", line 106, in wait_for_answer
    clue, ans_len = self._current_puzzle
ValueError: too many values to unpack (expected 2)
[2019-11-15 20:10:11] [ERROR] red: Exception in command 'layton'
Traceback (most recent call last):
  File "/usr/local/lib/python3.7/site-packages/discord/ext/commands/core.py", line 79, in wrapped
    ret = await coro(*args, **kwargs)
  File "/Users/vutheduc/Documents/Projects/PuzzleSoc/Social/Discord/CrypticBot/mycogs/layton/layton.py", line 68, in layton
    self._current_puzzle = grab_puzzle(id_)
  File "/Users/vutheduc/Documents/Projects/PuzzleSoc/Social/Discord/CrypticBot/mycogs/layton/layton.py", line 255, in grab_puzzle
    sol_txts += p.get_text(),
AttributeError: 'NoneType' object has no attribute 'get_text'
[2019-11-15 20:10:23] [ERROR] red: Exception in command 'layton'
Traceback (most recent call last):
  File "/usr/local/lib/python3.7/site-packages/discord/ext/commands/core.py", line 79, in wrapped
    ret = await coro(*args, **kwargs)
  File "/Users/vutheduc/Documents/Projects/PuzzleSoc/Social/Discord/CrypticBot/mycogs/layton/layton.py", line 68, in layton
    self._current_puzzle = grab_puzzle(id_)
  File "/Users/vutheduc/Documents/Projects/PuzzleSoc/Social/Discord/CrypticBot/mycogs/layton/layton.py", line 255, in grab_puzzle
    sol_txts += p.get_text(),
AttributeError: 'NoneType' object has no attribute 'get_text'
[2019-11-15 20:10:26] [ERROR] red: Exception in command 'layton'
Traceback (most recent call last):
  File "/usr/local/lib/python3.7/site-packages/discord/ext/commands/core.py", line 79, in wrapped
    ret = await coro(*args, **kwargs)
  File "/Users/vutheduc/Documents/Projects/PuzzleSoc/Social/Discord/CrypticBot/mycogs/layton/layton.py", line 76, in layton
    continue_ = await self.wait_for_answer(answers, 1, 900)
  File "/Users/vutheduc/Documents/Projects/PuzzleSoc/Social/Discord/CrypticBot/mycogs/layton/layton.py", line 108, in wait_for_answer
    "message", check=self.check_answer(answers), timeout=delay
  File "/Users/vutheduc/Documents/Projects/PuzzleSoc/Social/Discord/CrypticBot/mycogs/layton/layton.py", line 121, in check_answer
    answers = [ans.lower() for ans in answers]
UnboundLocalError: local variable 'answers' referenced before assignment
[2019-11-15 20:10:52] [ERROR] red: Exception in command 'layton'
Traceback (most recent call last):
  File "/usr/local/lib/python3.7/site-packages/discord/ext/commands/core.py", line 79, in wrapped
    ret = await coro(*args, **kwargs)
  File "/Users/vutheduc/Documents/Projects/PuzzleSoc/Social/Discord/CrypticBot/mycogs/layton/layton.py", line 68, in layton
    self._current_puzzle = grab_puzzle(id_)
  File "/Users/vutheduc/Documents/Projects/PuzzleSoc/Social/Discord/CrypticBot/mycogs/layton/layton.py", line 255, in grab_puzzle
    sol_txts += p.get_text(),
AttributeError: 'NoneType' object has no attribute 'get_text'
[2019-11-15 20:10:56] [ERROR] red: Exception in command 'layton'
Traceback (most recent call last):
  File "/usr/local/lib/python3.7/site-packages/discord/ext/commands/core.py", line 79, in wrapped
    ret = await coro(*args, **kwargs)
  File "/Users/vutheduc/Documents/Projects/PuzzleSoc/Social/Discord/CrypticBot/mycogs/layton/layton.py", line 76, in layton
    continue_ = await self.wait_for_answer(answers, 1, 900)
  File "/Users/vutheduc/Documents/Projects/PuzzleSoc/Social/Discord/CrypticBot/mycogs/layton/layton.py", line 108, in wait_for_answer
    "message", check=self.check_answer(answers), timeout=delay
  File "/Users/vutheduc/Documents/Projects/PuzzleSoc/Social/Discord/CrypticBot/mycogs/layton/layton.py", line 121, in check_answer
    answers = [ans.lower() for ans in answers]
  File "/Users/vutheduc/Documents/Projects/PuzzleSoc/Social/Discord/CrypticBot/mycogs/layton/layton.py", line 121, in <listcomp>
    answers = [ans.lower() for ans in answers]
AttributeError: 'NoneType' object has no attribute 'lower'
[2019-11-15 20:11:48] [ERROR] red: Exception in command 'layton'
Traceback (most recent call last):
  File "/usr/local/lib/python3.7/site-packages/discord/ext/commands/core.py", line 79, in wrapped
    ret = await coro(*args, **kwargs)
  File "/Users/vutheduc/Documents/Projects/PuzzleSoc/Social/Discord/CrypticBot/mycogs/layton/layton.py", line 68, in layton
    self._current_puzzle = grab_puzzle(id_)
  File "/Users/vutheduc/Documents/Projects/PuzzleSoc/Social/Discord/CrypticBot/mycogs/layton/layton.py", line 255, in grab_puzzle
    sol_txts += p.get_text(),
AttributeError: 'NoneType' object has no attribute 'get_text'
[2019-11-15 20:11:54] [ERROR] red: Exception in command 'layton'
Traceback (most recent call last):
  File "/usr/local/lib/python3.7/site-packages/discord/ext/commands/core.py", line 79, in wrapped
    ret = await coro(*args, **kwargs)
  File "/Users/vutheduc/Documents/Projects/PuzzleSoc/Social/Discord/CrypticBot/mycogs/layton/layton.py", line 68, in layton
    self._current_puzzle = grab_puzzle(id_)
  File "/Users/vutheduc/Documents/Projects/PuzzleSoc/Social/Discord/CrypticBot/mycogs/layton/layton.py", line 255, in grab_puzzle
    sol_txts += p.get_text(),
AttributeError: 'NoneType' object has no attribute 'get_text'
[2019-11-15 20:13:01] [ERROR] red: Exception in command 'layton'
Traceback (most recent call last):
  File "/usr/local/lib/python3.7/site-packages/discord/ext/commands/core.py", line 79, in wrapped
    ret = await coro(*args, **kwargs)
  File "/Users/vutheduc/Documents/Projects/PuzzleSoc/Social/Discord/CrypticBot/mycogs/layton/layton.py", line 65, in layton
    if self._current_puzzle is None or not self._current_puzzle['set_answer']:
KeyError: 'set_answer'
[2019-11-15 20:13:03] [ERROR] red: Exception in command 'layton'
Traceback (most recent call last):
  File "/usr/local/lib/python3.7/site-packages/discord/ext/commands/core.py", line 79, in wrapped
    ret = await coro(*args, **kwargs)
  File "/Users/vutheduc/Documents/Projects/PuzzleSoc/Social/Discord/CrypticBot/mycogs/layton/layton.py", line 65, in layton
    if self._current_puzzle is None or not self._current_puzzle['set_answer']:
KeyError: 'set_answer'
[2019-11-15 20:13:06] [ERROR] red: Exception in command 'layton'
Traceback (most recent call last):
  File "/usr/local/lib/python3.7/site-packages/discord/ext/commands/core.py", line 79, in wrapped
    ret = await coro(*args, **kwargs)
  File "/Users/vutheduc/Documents/Projects/PuzzleSoc/Social/Discord/CrypticBot/mycogs/layton/layton.py", line 65, in layton
    if self._current_puzzle is None or not self._current_puzzle['set_answer']:
KeyError: 'set_answer'
[2019-11-15 20:13:08] [ERROR] red: Exception in command 'layton'
Traceback (most recent call last):
  File "/usr/local/lib/python3.7/site-packages/discord/ext/commands/core.py", line 79, in wrapped
    ret = await coro(*args, **kwargs)
  File "/Users/vutheduc/Documents/Projects/PuzzleSoc/Social/Discord/CrypticBot/mycogs/layton/layton.py", line 65, in layton
    if self._current_puzzle is None or not self._current_puzzle['set_answer']:
KeyError: 'set_answer'
[2019-11-15 20:13:11] [ERROR] red: Exception in command 'layton'
Traceback (most recent call last):
  File "/usr/local/lib/python3.7/site-packages/discord/ext/commands/core.py", line 79, in wrapped
    ret = await coro(*args, **kwargs)
  File "/Users/vutheduc/Documents/Projects/PuzzleSoc/Social/Discord/CrypticBot/mycogs/layton/layton.py", line 65, in layton
    if self._current_puzzle is None or not self._current_puzzle['set_answer']:
KeyError: 'set_answer'
[2019-11-15 20:13:15] [ERROR] red: Exception in command 'layton'
Traceback (most recent call last):
  File "/usr/local/lib/python3.7/site-packages/discord/ext/commands/core.py", line 79, in wrapped
    ret = await coro(*args, **kwargs)
  File "/Users/vutheduc/Documents/Projects/PuzzleSoc/Social/Discord/CrypticBot/mycogs/layton/layton.py", line 65, in layton
    if self._current_puzzle is None or not self._current_puzzle['set_answer']:
KeyError: 'set_answer'
[2019-11-15 20:13:17] [ERROR] red: Exception in command 'layton'
Traceback (most recent call last):
  File "/usr/local/lib/python3.7/site-packages/discord/ext/commands/core.py", line 79, in wrapped
    ret = await coro(*args, **kwargs)
  File "/Users/vutheduc/Documents/Projects/PuzzleSoc/Social/Discord/CrypticBot/mycogs/layton/layton.py", line 65, in layton
    if self._current_puzzle is None or not self._current_puzzle['set_answer']:
KeyError: 'set_answer'
[2019-11-15 20:13:19] [ERROR] red: Exception in command 'layton'
Traceback (most recent call last):
  File "/usr/local/lib/python3.7/site-packages/discord/ext/commands/core.py", line 79, in wrapped
    ret = await coro(*args, **kwargs)
  File "/Users/vutheduc/Documents/Projects/PuzzleSoc/Social/Discord/CrypticBot/mycogs/layton/layton.py", line 65, in layton
    if self._current_puzzle is None or not self._current_puzzle['set_answer']:
KeyError: 'set_answer'
[2019-11-15 20:13:29] [ERROR] red: Exception in command 'layton'
Traceback (most recent call last):
  File "/usr/local/lib/python3.7/site-packages/discord/ext/commands/core.py", line 79, in wrapped
    ret = await coro(*args, **kwargs)
  File "/Users/vutheduc/Documents/Projects/PuzzleSoc/Social/Discord/CrypticBot/mycogs/layton/layton.py", line 65, in layton
    if self._current_puzzle is None or not self._current_puzzle['set_answer']:
KeyError: 'set_answer'
[2019-11-15 20:13:33] [ERROR] red: Exception in command 'layton'
Traceback (most recent call last):
  File "/usr/local/lib/python3.7/site-packages/discord/ext/commands/core.py", line 79, in wrapped
    ret = await coro(*args, **kwargs)
  File "/Users/vutheduc/Documents/Projects/PuzzleSoc/Social/Discord/CrypticBot/mycogs/layton/layton.py", line 65, in layton
    if self._current_puzzle is None or not self._current_puzzle['set_answer']:
KeyError: 'set_answer'
[2019-11-15 22:52:11] [INFO] red.main: Keyboard interrupt detected. Quitting...
[2019-11-15 22:54:16] [ERROR] red: Exception in command 'layton'
Traceback (most recent call last):
  File "/usr/local/lib/python3.7/site-packages/discord/ext/commands/core.py", line 79, in wrapped
    ret = await coro(*args, **kwargs)
  File "/Users/vutheduc/Documents/Projects/PuzzleSoc/Social/Discord/CrypticBot/mycogs/layton/layton.py", line 68, in layton
    self._current_puzzle = grab_puzzle(id_)
  File "/Users/vutheduc/Documents/Projects/PuzzleSoc/Social/Discord/CrypticBot/mycogs/layton/layton.py", line 256, in grab_puzzle
    sol_txts += p.get_text(),
AttributeError: 'NoneType' object has no attribute 'get_text'
[2019-11-15 23:10:58] [ERROR] red: Exception in command 'layton'
Traceback (most recent call last):
  File "/usr/local/lib/python3.7/site-packages/discord/ext/commands/core.py", line 79, in wrapped
    ret = await coro(*args, **kwargs)
  File "/Users/vutheduc/Documents/Projects/PuzzleSoc/Social/Discord/CrypticBot/mycogs/layton/layton.py", line 76, in layton
    "\n" + f"*This is puzzle {self._current_puzzle['number']} from {self._current_puzzle['game']}. ID: {self._current_puzzle['id']}*")
KeyError: 'id'
[2019-11-16 03:04:34] [ERROR] red: Package loading failed
Traceback (most recent call last):
  File "/usr/local/lib/python3.7/site-packages/redbot/core/core_commands.py", line 106, in _load
    await bot.load_extension(spec)
  File "/usr/local/lib/python3.7/site-packages/redbot/core/bot.py", line 293, in load_extension
    lib = spec.loader.load_module()
  File "<frozen importlib._bootstrap_external>", line 407, in _check_name_wrapper
  File "<frozen importlib._bootstrap_external>", line 907, in load_module
  File "<frozen importlib._bootstrap_external>", line 732, in load_module
  File "<frozen importlib._bootstrap>", line 265, in _load_module_shim
  File "<frozen importlib._bootstrap>", line 696, in _load
  File "<frozen importlib._bootstrap>", line 677, in _load_unlocked
  File "<frozen importlib._bootstrap_external>", line 728, in exec_module
  File "<frozen importlib._bootstrap>", line 219, in _call_with_frames_removed
  File "/Users/vutheduc/Documents/Projects/PuzzleSoc/Social/Discord/CrypticBot/mycogs/layton/__init__.py", line 1, in <module>
    from .layton import Layton
  File "/Users/vutheduc/Documents/Projects/PuzzleSoc/Social/Discord/CrypticBot/mycogs/layton/layton.py", line 170
    async def layton_solve(self, ctx: commands.Context, *puzzle_id : str = None):
                                                                         ^
SyntaxError: invalid syntax
[2019-11-16 03:05:04] [ERROR] red: Package loading failed
Traceback (most recent call last):
  File "/usr/local/lib/python3.7/site-packages/redbot/core/core_commands.py", line 106, in _load
    await bot.load_extension(spec)
  File "/usr/local/lib/python3.7/site-packages/redbot/core/bot.py", line 293, in load_extension
    lib = spec.loader.load_module()
  File "<frozen importlib._bootstrap_external>", line 407, in _check_name_wrapper
  File "<frozen importlib._bootstrap_external>", line 907, in load_module
  File "<frozen importlib._bootstrap_external>", line 732, in load_module
  File "<frozen importlib._bootstrap>", line 265, in _load_module_shim
  File "<frozen importlib._bootstrap>", line 696, in _load
  File "<frozen importlib._bootstrap>", line 677, in _load_unlocked
  File "<frozen importlib._bootstrap_external>", line 728, in exec_module
  File "<frozen importlib._bootstrap>", line 219, in _call_with_frames_removed
  File "/Users/vutheduc/Documents/Projects/PuzzleSoc/Social/Discord/CrypticBot/mycogs/layton/__init__.py", line 1, in <module>
    from .layton import Layton
  File "/Users/vutheduc/Documents/Projects/PuzzleSoc/Social/Discord/CrypticBot/mycogs/layton/layton.py", line 41, in <module>
    class Layton(commands.Cog):
  File "/Users/vutheduc/Documents/Projects/PuzzleSoc/Social/Discord/CrypticBot/mycogs/layton/layton.py", line 169, in Layton
    @cryptic.command(name='solve')
NameError: name 'cryptic' is not defined
[2019-11-16 03:06:32] [ERROR] red: Exception in command 'layton solve'
Traceback (most recent call last):
  File "/usr/local/lib/python3.7/site-packages/discord/ext/commands/core.py", line 79, in wrapped
    ret = await coro(*args, **kwargs)
  File "/Users/vutheduc/Documents/Projects/PuzzleSoc/Social/Discord/CrypticBot/mycogs/layton/layton.py", line 177, in layton_solve
    puzzle = grab_puzzle(puzzle_id)
  File "/Users/vutheduc/Documents/Projects/PuzzleSoc/Social/Discord/CrypticBot/mycogs/layton/layton.py", line 201, in grab_puzzle
    'URL': "https://layton.fandom.com/wiki/Puzzle:" + puzzle_id
TypeError: can only concatenate str (not "tuple") to str
[2019-11-16 03:08:09] [ERROR] red: Exception in command 'layton solve'
Traceback (most recent call last):
  File "/usr/local/lib/python3.7/site-packages/discord/ext/commands/core.py", line 79, in wrapped
    ret = await coro(*args, **kwargs)
  File "/Users/vutheduc/Documents/Projects/PuzzleSoc/Social/Discord/CrypticBot/mycogs/layton/layton.py", line 177, in layton_solve
    puzzle_id = puzzle_id[0]
  File "/Users/vutheduc/Documents/Projects/PuzzleSoc/Social/Discord/CrypticBot/mycogs/layton/layton.py", line 201, in grab_puzzle
    'id': puzzle_id,
TypeError: can only concatenate str (not "tuple") to str
[2019-11-16 03:09:12] [ERROR] red: Exception in command 'layton solve'
Traceback (most recent call last):
  File "/usr/local/lib/python3.7/site-packages/discord/ext/commands/core.py", line 79, in wrapped
    ret = await coro(*args, **kwargs)
  File "/Users/vutheduc/Documents/Projects/PuzzleSoc/Social/Discord/CrypticBot/mycogs/layton/layton.py", line 177, in layton_solve
    puzzle = grab_puzzle(puzzle_id[0])
IndexError: tuple index out of range
[2019-11-16 03:10:59] [ERROR] red: Exception in command 'layton solve'
Traceback (most recent call last):
  File "/usr/local/lib/python3.7/site-packages/discord/ext/commands/core.py", line 79, in wrapped
    ret = await coro(*args, **kwargs)
  File "/Users/vutheduc/Documents/Projects/PuzzleSoc/Social/Discord/CrypticBot/mycogs/layton/layton.py", line 177, in layton_solve
    puzzle = grab_puzzle(puzzle_id)
  File "/Users/vutheduc/Documents/Projects/PuzzleSoc/Social/Discord/CrypticBot/mycogs/layton/layton.py", line 201, in grab_puzzle
    'URL': "https://layton.fandom.com/wiki/Puzzle:" + puzzle_id
TypeError: can only concatenate str (not "tuple") to str
[2019-11-16 03:11:20] [ERROR] red: Exception in command 'layton solve'
Traceback (most recent call last):
  File "/usr/local/lib/python3.7/site-packages/discord/ext/commands/core.py", line 79, in wrapped
    ret = await coro(*args, **kwargs)
  File "/Users/vutheduc/Documents/Projects/PuzzleSoc/Social/Discord/CrypticBot/mycogs/layton/layton.py", line 178, in layton_solve
    puzzle = grab_puzzle(puzzle_id)
  File "/Users/vutheduc/Documents/Projects/PuzzleSoc/Social/Discord/CrypticBot/mycogs/layton/layton.py", line 202, in grab_puzzle
    'URL': "https://layton.fandom.com/wiki/Puzzle:" + puzzle_id
TypeError: can only concatenate str (not "tuple") to str
[2019-11-16 03:12:05] [ERROR] red: Exception in command 'layton solve'
Traceback (most recent call last):
  File "/usr/local/lib/python3.7/site-packages/discord/ext/commands/core.py", line 79, in wrapped
    ret = await coro(*args, **kwargs)
  File "/Users/vutheduc/Documents/Projects/PuzzleSoc/Social/Discord/CrypticBot/mycogs/layton/layton.py", line 178, in layton_solve
    puzzle = grab_puzzle(puzzle_id[0])
IndexError: tuple index out of range
[2019-11-16 03:12:30] [ERROR] red: Exception in command 'layton'
Traceback (most recent call last):
  File "/usr/local/lib/python3.7/site-packages/discord/ext/commands/core.py", line 79, in wrapped
    ret = await coro(*args, **kwargs)
  File "/Users/vutheduc/Documents/Projects/PuzzleSoc/Social/Discord/CrypticBot/mycogs/layton/layton.py", line 65, in layton
    if self._current_puzzle is None or 'set_answer' not in self._current_puzzle:
TypeError: argument of type 'bool' is not iterable
[2019-11-16 03:13:28] [ERROR] red: Exception in command 'layton solve'
Traceback (most recent call last):
  File "/usr/local/lib/python3.7/site-packages/discord/ext/commands/core.py", line 79, in wrapped
    ret = await coro(*args, **kwargs)
  File "/Users/vutheduc/Documents/Projects/PuzzleSoc/Social/Discord/CrypticBot/mycogs/layton/layton.py", line 178, in layton_solve
    puzzle = grab_puzzle(puzzle_id[0])
IndexError: tuple index out of range
[2019-11-16 23:49:06] [ERROR] red: Package loading failed
Traceback (most recent call last):
  File "/usr/local/lib/python3.7/site-packages/redbot/core/core_commands.py", line 106, in _load
    await bot.load_extension(spec)
  File "/usr/local/lib/python3.7/site-packages/redbot/core/bot.py", line 293, in load_extension
    lib = spec.loader.load_module()
  File "<frozen importlib._bootstrap_external>", line 407, in _check_name_wrapper
  File "<frozen importlib._bootstrap_external>", line 907, in load_module
  File "<frozen importlib._bootstrap_external>", line 732, in load_module
  File "<frozen importlib._bootstrap>", line 265, in _load_module_shim
  File "<frozen importlib._bootstrap>", line 696, in _load
  File "<frozen importlib._bootstrap>", line 677, in _load_unlocked
  File "<frozen importlib._bootstrap_external>", line 728, in exec_module
  File "<frozen importlib._bootstrap>", line 219, in _call_with_frames_removed
  File "/Users/vutheduc/Documents/Projects/PuzzleSoc/Social/Discord/CrypticBot/mycogs/layton/__init__.py", line 1, in <module>
    from .layton import Layton
  File "/Users/vutheduc/Documents/Projects/PuzzleSoc/Social/Discord/CrypticBot/mycogs/layton/layton.py", line 49, in <module>
    class Layton(commands.Cog):
  File "/Users/vutheduc/Documents/Projects/PuzzleSoc/Social/Discord/CrypticBot/mycogs/layton/layton.py", line 164, in Layton
    @cryptic.command(name='modview')
NameError: name 'cryptic' is not defined
[2019-11-16 23:58:25] [ERROR] red: Exception in command 'layton'
Traceback (most recent call last):
  File "/usr/local/lib/python3.7/site-packages/discord/ext/commands/core.py", line 79, in wrapped
    ret = await coro(*args, **kwargs)
  File "/Users/vutheduc/Documents/Projects/PuzzleSoc/Social/Discord/CrypticBot/mycogs/layton/layton.py", line 76, in layton
    self._current_puzzle = grab_puzzle(id_)
  File "/Users/vutheduc/Documents/Projects/PuzzleSoc/Social/Discord/CrypticBot/mycogs/layton/layton.py", line 296, in grab_puzzle
    puzzle_dict['solution'] = '\n'.join(sol_txts).split('A big thanks to')[0].split('UK Version')[0].split('UK Version')[1]
IndexError: list index out of range
[2019-11-16 23:59:53] [ERROR] red: Exception in command 'layton'
Traceback (most recent call last):
  File "/usr/local/lib/python3.7/site-packages/discord/ext/commands/core.py", line 79, in wrapped
    ret = await coro(*args, **kwargs)
  File "/Users/vutheduc/Documents/Projects/PuzzleSoc/Social/Discord/CrypticBot/mycogs/layton/layton.py", line 76, in layton
    self._current_puzzle = grab_puzzle(id_)
  File "/Users/vutheduc/Documents/Projects/PuzzleSoc/Social/Discord/CrypticBot/mycogs/layton/layton.py", line 298, in grab_puzzle
    solution_txt = solution_txt.split('UK Version')[0].split('UK Version')[1]
IndexError: list index out of range
[2019-11-17 12:22:59] [ERROR] red: Exception in command 'layton solve'
Traceback (most recent call last):
  File "/usr/local/lib/python3.7/site-packages/discord/ext/commands/core.py", line 79, in wrapped
    ret = await coro(*args, **kwargs)
  File "/Users/vutheduc/Documents/Projects/PuzzleSoc/Social/Discord/CrypticBot/mycogs/layton/layton.py", line 186, in layton_solve
    puzzle = grab_puzzle(puzzle_id[0])
  File "/Users/vutheduc/Documents/Projects/PuzzleSoc/Social/Discord/CrypticBot/mycogs/layton/layton.py", line 255, in grab_puzzle
    puzzle_span = puzzle_soup.find('span', id='Puzzle').parent.parent
AttributeError: 'NoneType' object has no attribute 'parent'
[2019-11-17 12:50:55] [ERROR] red: Package loading failed
Traceback (most recent call last):
  File "/usr/local/lib/python3.7/site-packages/redbot/core/core_commands.py", line 106, in _load
    await bot.load_extension(spec)
  File "/usr/local/lib/python3.7/site-packages/redbot/core/bot.py", line 293, in load_extension
    lib = spec.loader.load_module()
  File "<frozen importlib._bootstrap_external>", line 407, in _check_name_wrapper
  File "<frozen importlib._bootstrap_external>", line 907, in load_module
  File "<frozen importlib._bootstrap_external>", line 732, in load_module
  File "<frozen importlib._bootstrap>", line 265, in _load_module_shim
  File "<frozen importlib._bootstrap>", line 696, in _load
  File "<frozen importlib._bootstrap>", line 677, in _load_unlocked
  File "<frozen importlib._bootstrap_external>", line 728, in exec_module
  File "<frozen importlib._bootstrap>", line 219, in _call_with_frames_removed
  File "/Users/vutheduc/Documents/Projects/PuzzleSoc/Social/Discord/CrypticBot/mycogs/layton/__init__.py", line 1, in <module>
    from .layton import Layton
  File "/Users/vutheduc/Documents/Projects/PuzzleSoc/Social/Discord/CrypticBot/mycogs/layton/layton.py", line 49, in <module>
    class Layton(commands.Cog):
  File "/Users/vutheduc/Documents/Projects/PuzzleSoc/Social/Discord/CrypticBot/mycogs/layton/layton.py", line 202, in Layton
    @layton.commands(name='hint')
TypeError: 'set' object is not callable
[2019-11-17 12:52:09] [ERROR] red: Exception in command 'layton hint'
Traceback (most recent call last):
  File "/usr/local/lib/python3.7/site-packages/discord/ext/commands/core.py", line 79, in wrapped
    ret = await coro(*args, **kwargs)
  File "/Users/vutheduc/Documents/Projects/PuzzleSoc/Social/Discord/CrypticBot/mycogs/layton/layton.py", line 208, in layton_hint
    if not hints:
NameError: name 'hints' is not defined
[2019-11-17 12:59:43] [ERROR] red: Exception in command 'layton'
Traceback (most recent call last):
  File "/usr/local/lib/python3.7/site-packages/discord/ext/commands/core.py", line 79, in wrapped
    ret = await coro(*args, **kwargs)
  File "/Users/vutheduc/Documents/Projects/PuzzleSoc/Social/Discord/CrypticBot/mycogs/layton/layton.py", line 76, in layton
    self._current_puzzle = grab_puzzle(id_)
  File "/Users/vutheduc/Documents/Projects/PuzzleSoc/Social/Discord/CrypticBot/mycogs/layton/layton.py", line 367, in grab_puzzle
    hint_list + (i + 1, hint),
TypeError: can only concatenate list (not "tuple") to list
[2019-11-17 13:00:01] [ERROR] red: Exception in command 'layton'
Traceback (most recent call last):
  File "/usr/local/lib/python3.7/site-packages/discord/ext/commands/core.py", line 79, in wrapped
    ret = await coro(*args, **kwargs)
  File "/Users/vutheduc/Documents/Projects/PuzzleSoc/Social/Discord/CrypticBot/mycogs/layton/layton.py", line 87, in layton
    if self._current_puzzles['hints']:
AttributeError: 'Layton' object has no attribute '_current_puzzles'
[2019-11-17 13:13:37] [ERROR] red: Package loading failed
Traceback (most recent call last):
  File "/usr/local/lib/python3.7/site-packages/redbot/core/core_commands.py", line 106, in _load
    await bot.load_extension(spec)
  File "/usr/local/lib/python3.7/site-packages/redbot/core/bot.py", line 293, in load_extension
    lib = spec.loader.load_module()
  File "<frozen importlib._bootstrap_external>", line 407, in _check_name_wrapper
  File "<frozen importlib._bootstrap_external>", line 907, in load_module
  File "<frozen importlib._bootstrap_external>", line 732, in load_module
  File "<frozen importlib._bootstrap>", line 265, in _load_module_shim
  File "<frozen importlib._bootstrap>", line 696, in _load
  File "<frozen importlib._bootstrap>", line 677, in _load_unlocked
  File "<frozen importlib._bootstrap_external>", line 728, in exec_module
  File "<frozen importlib._bootstrap>", line 219, in _call_with_frames_removed
  File "/Users/vutheduc/Documents/Projects/PuzzleSoc/Social/Discord/CrypticBot/mycogs/layton/__init__.py", line 1, in <module>
    from .layton import Layton
  File "/Users/vutheduc/Documents/Projects/PuzzleSoc/Social/Discord/CrypticBot/mycogs/layton/layton.py", line 223
    async def layton_setanswer(self, ctx: commands.Context, *puzzle_id: str, *answer: str):
                                                                             ^
SyntaxError: invalid syntax
[2019-11-17 13:16:39] [ERROR] red: Exception in command 'layton setanswer'
Traceback (most recent call last):
  File "/usr/local/lib/python3.7/site-packages/discord/ext/commands/core.py", line 79, in wrapped
    ret = await coro(*args, **kwargs)
  File "/Users/vutheduc/Documents/Projects/PuzzleSoc/Social/Discord/CrypticBot/mycogs/layton/layton.py", line 238, in layton_setanswer
    puzzles = yaml.safe_dump(self._puzzles, f)
  File "/usr/local/lib/python3.7/site-packages/yaml/__init__.py", line 306, in safe_dump
    return dump_all([data], stream, Dumper=SafeDumper, **kwds)
  File "/usr/local/lib/python3.7/site-packages/yaml/__init__.py", line 278, in dump_all
    dumper.represent(data)
  File "/usr/local/lib/python3.7/site-packages/yaml/representer.py", line 28, in represent
    self.serialize(node)
  File "/usr/local/lib/python3.7/site-packages/yaml/serializer.py", line 54, in serialize
    self.serialize_node(node, None, None)
  File "/usr/local/lib/python3.7/site-packages/yaml/serializer.py", line 108, in serialize_node
    self.serialize_node(value, node, key)
  File "/usr/local/lib/python3.7/site-packages/yaml/serializer.py", line 98, in serialize_node
    self.serialize_node(item, node, index)
  File "/usr/local/lib/python3.7/site-packages/yaml/serializer.py", line 90, in serialize_node
    style=node.style))
  File "/usr/local/lib/python3.7/site-packages/yaml/emitter.py", line 115, in emit
    self.state()
  File "/usr/local/lib/python3.7/site-packages/yaml/emitter.py", line 393, in expect_first_block_mapping_key
    return self.expect_block_mapping_key(first=True)
  File "/usr/local/lib/python3.7/site-packages/yaml/emitter.py", line 403, in expect_block_mapping_key
    self.expect_node(mapping=True, simple_key=True)
  File "/usr/local/lib/python3.7/site-packages/yaml/emitter.py", line 244, in expect_node
    self.expect_scalar()
  File "/usr/local/lib/python3.7/site-packages/yaml/emitter.py", line 268, in expect_scalar
    self.process_scalar()
  File "/usr/local/lib/python3.7/site-packages/yaml/emitter.py", line 533, in process_scalar
    self.write_plain(self.analysis.scalar, split)
  File "/usr/local/lib/python3.7/site-packages/yaml/emitter.py", line 1132, in write_plain
    self.stream.write(data)
io.UnsupportedOperation: not writable
[2019-11-17 13:18:39] [ERROR] red: Exception in command 'layton setanswer'
Traceback (most recent call last):
  File "/usr/local/lib/python3.7/site-packages/discord/ext/commands/core.py", line 79, in wrapped
    ret = await coro(*args, **kwargs)
  File "/Users/vutheduc/Documents/Projects/PuzzleSoc/Social/Discord/CrypticBot/mycogs/layton/layton.py", line 238, in layton_setanswer
    puzzles = yaml.safe_dump(self._puzzles, f)
  File "/usr/local/lib/python3.7/site-packages/yaml/__init__.py", line 306, in safe_dump
    return dump_all([data], stream, Dumper=SafeDumper, **kwds)
  File "/usr/local/lib/python3.7/site-packages/yaml/__init__.py", line 278, in dump_all
    dumper.represent(data)
  File "/usr/local/lib/python3.7/site-packages/yaml/representer.py", line 28, in represent
    self.serialize(node)
  File "/usr/local/lib/python3.7/site-packages/yaml/serializer.py", line 54, in serialize
    self.serialize_node(node, None, None)
  File "/usr/local/lib/python3.7/site-packages/yaml/serializer.py", line 108, in serialize_node
    self.serialize_node(value, node, key)
  File "/usr/local/lib/python3.7/site-packages/yaml/serializer.py", line 98, in serialize_node
    self.serialize_node(item, node, index)
  File "/usr/local/lib/python3.7/site-packages/yaml/serializer.py", line 90, in serialize_node
    style=node.style))
  File "/usr/local/lib/python3.7/site-packages/yaml/emitter.py", line 115, in emit
    self.state()
  File "/usr/local/lib/python3.7/site-packages/yaml/emitter.py", line 393, in expect_first_block_mapping_key
    return self.expect_block_mapping_key(first=True)
  File "/usr/local/lib/python3.7/site-packages/yaml/emitter.py", line 403, in expect_block_mapping_key
    self.expect_node(mapping=True, simple_key=True)
  File "/usr/local/lib/python3.7/site-packages/yaml/emitter.py", line 244, in expect_node
    self.expect_scalar()
  File "/usr/local/lib/python3.7/site-packages/yaml/emitter.py", line 268, in expect_scalar
    self.process_scalar()
  File "/usr/local/lib/python3.7/site-packages/yaml/emitter.py", line 533, in process_scalar
    self.write_plain(self.analysis.scalar, split)
  File "/usr/local/lib/python3.7/site-packages/yaml/emitter.py", line 1132, in write_plain
    self.stream.write(data)
io.UnsupportedOperation: not writable
[2019-11-17 13:55:33] [ERROR] red: Exception in command 'layton'
Traceback (most recent call last):
  File "/usr/local/lib/python3.7/site-packages/discord/ext/commands/core.py", line 79, in wrapped
    ret = await coro(*args, **kwargs)
  File "/Users/vutheduc/Documents/Projects/PuzzleSoc/Social/Discord/CrypticBot/mycogs/layton/layton.py", line 84, in layton
    continue_ = await self.wait_for_answer(answers, 1, 900)
  File "/Users/vutheduc/Documents/Projects/PuzzleSoc/Social/Discord/CrypticBot/mycogs/layton/layton.py", line 119, in wait_for_answer
    "message", check=self.check_answer(answers), timeout=delay
  File "/Users/vutheduc/Documents/Projects/PuzzleSoc/Social/Discord/CrypticBot/mycogs/layton/layton.py", line 137, in check_answer
    answers = [ans.lower() for ans in answers]
  File "/Users/vutheduc/Documents/Projects/PuzzleSoc/Social/Discord/CrypticBot/mycogs/layton/layton.py", line 137, in <listcomp>
    answers = [ans.lower() for ans in answers]
AttributeError: 'int' object has no attribute 'lower'
[2019-11-17 14:01:51] [ERROR] red: Package loading failed
Traceback (most recent call last):
  File "/usr/local/lib/python3.7/site-packages/redbot/core/core_commands.py", line 106, in _load
    await bot.load_extension(spec)
  File "/usr/local/lib/python3.7/site-packages/redbot/core/bot.py", line 293, in load_extension
    lib = spec.loader.load_module()
  File "<frozen importlib._bootstrap_external>", line 407, in _check_name_wrapper
  File "<frozen importlib._bootstrap_external>", line 907, in load_module
  File "<frozen importlib._bootstrap_external>", line 732, in load_module
  File "<frozen importlib._bootstrap>", line 265, in _load_module_shim
  File "<frozen importlib._bootstrap>", line 696, in _load
  File "<frozen importlib._bootstrap>", line 677, in _load_unlocked
  File "<frozen importlib._bootstrap_external>", line 728, in exec_module
  File "<frozen importlib._bootstrap>", line 219, in _call_with_frames_removed
  File "/Users/vutheduc/Documents/Projects/PuzzleSoc/Social/Discord/CrypticBot/mycogs/layton/__init__.py", line 1, in <module>
    from .layton import Layton
  File "/Users/vutheduc/Documents/Projects/PuzzleSoc/Social/Discord/CrypticBot/mycogs/layton/layton.py", line 144
    return any([guess == ans for ans in answers)
                                               ^
SyntaxError: invalid syntax
[2019-11-17 14:02:17] [ERROR] red: Exception in command 'layton'
Traceback (most recent call last):
  File "/usr/local/lib/python3.7/site-packages/discord/ext/commands/core.py", line 79, in wrapped
    ret = await coro(*args, **kwargs)
  File "/Users/vutheduc/Documents/Projects/PuzzleSoc/Social/Discord/CrypticBot/mycogs/layton/layton.py", line 84, in layton
    continue_ = await self.wait_for_answer(answers, 1, 900)
  File "/Users/vutheduc/Documents/Projects/PuzzleSoc/Social/Discord/CrypticBot/mycogs/layton/layton.py", line 129, in wait_for_answer
    await ctx.send(f"\"{random.choice(_SUCCESS_SOUNDBITES)}\"\n\n**{title} - Solution**\n{solution}!\n" + '\n'.join(sol_imgs))
NameError: name 'ctx' is not defined
[2019-11-17 14:12:29] [ERROR] red: Exception in command 'layton'
Traceback (most recent call last):
  File "/usr/local/lib/python3.7/site-packages/discord/ext/commands/core.py", line 79, in wrapped
    ret = await coro(*args, **kwargs)
  File "/Users/vutheduc/Documents/Projects/PuzzleSoc/Social/Discord/CrypticBot/mycogs/layton/layton.py", line 84, in layton
    continue_ = await self.wait_for_answer(answers, 1, 900)
  File "/Users/vutheduc/Documents/Projects/PuzzleSoc/Social/Discord/CrypticBot/mycogs/layton/layton.py", line 129, in wait_for_answer
    await self.ctx.send(f"\"{random.choice(_SUCCESS_SOUNDBITES)}\"\n\n**{title} - Solution**\n{solution}!\n" + '\n'.join(sol_imgs))
NameError: name 'ctx' is not defined
[2019-11-17 14:28:27] [ERROR] red: Exception in command 'layton'
Traceback (most recent call last):
  File "/usr/local/lib/python3.7/site-packages/discord/ext/commands/core.py", line 79, in wrapped
    ret = await coro(*args, **kwargs)
  File "/Users/vutheduc/Documents/Projects/PuzzleSoc/Social/Discord/CrypticBot/mycogs/layton/layton.py", line 84, in layton
    self._current_puzzle['set_answer'] = True
  File "/Users/vutheduc/Documents/Projects/PuzzleSoc/Social/Discord/CrypticBot/mycogs/layton/layton.py", line 130, in wait_for_answer
    await ctx.send(f"You got it, {message.author.display_name}! For solving " + self._current_puzzle['id'] +
TypeError: 'NoneType' object is not subscriptable
[2019-11-18 14:40:51] [ERROR] red: Exception in command 'layton'
Traceback (most recent call last):
  File "/usr/local/lib/python3.7/site-packages/discord/ext/commands/core.py", line 79, in wrapped
    ret = await coro(*args, **kwargs)
  File "/Users/vutheduc/Documents/Projects/PuzzleSoc/Social/Discord/CrypticBot/mycogs/layton/layton.py", line 88, in layton
    text += f"This puzzle is not interactive (yet?). Type \"?layton solve\" to check your answer!"
UnboundLocalError: local variable 'text' referenced before assignment
[2019-11-19 16:07:09] [INFO] red.main: Keyboard interrupt detected. Quitting...
[2019-11-19 17:14:15] [INFO] red.main: Keyboard interrupt detected. Quitting...
[2019-11-19 17:27:51] [INFO] red.main: Keyboard interrupt detected. Quitting...
[2019-12-06 11:31:26] [INFO] red.main: Keyboard interrupt detected. Quitting...
[2019-12-09 11:15:31] [WARNING] red: Detected significant difference (64 seconds) in system clock to discord's clock. Any time sensitive code may fail.
[2019-12-09 22:31:26] [WARNING] red: Detected significant difference (63 seconds) in system clock to discord's clock. Any time sensitive code may fail.
[2019-12-10 11:18:17] [WARNING] red: Detected significant difference (68 seconds) in system clock to discord's clock. Any time sensitive code may fail.
[2019-12-10 12:21:59] [WARNING] red: Detected significant difference (67 seconds) in system clock to discord's clock. Any time sensitive code may fail.
