[2019-11-10 18:17:55] [ERROR] red: Package loading failed
Traceback (most recent call last):
  File "/usr/local/lib/python3.7/site-packages/redbot/core/core_commands.py", line 106, in _load
    await bot.load_extension(spec)
  File "/usr/local/lib/python3.7/site-packages/redbot/core/bot.py", line 296, in load_extension
    raise discord.ClientException(f"extension {name} does not have a setup function")
discord.errors.ClientException: extension cryptic does not have a setup function
[2019-11-10 18:19:17] [ERROR] red: Package loading failed
Traceback (most recent call last):
  File "/usr/local/lib/python3.7/site-packages/redbot/core/core_commands.py", line 106, in _load
    await bot.load_extension(spec)
  File "/usr/local/lib/python3.7/site-packages/redbot/core/bot.py", line 296, in load_extension
    raise discord.ClientException(f"extension {name} does not have a setup function")
discord.errors.ClientException: extension cryptic does not have a setup function
[2019-11-10 18:21:20] [ERROR] red: Package loading failed
Traceback (most recent call last):
  File "/usr/local/lib/python3.7/site-packages/redbot/core/core_commands.py", line 106, in _load
    await bot.load_extension(spec)
  File "/usr/local/lib/python3.7/site-packages/redbot/core/bot.py", line 296, in load_extension
    raise discord.ClientException(f"extension {name} does not have a setup function")
discord.errors.ClientException: extension cryptic does not have a setup function
[2019-11-10 18:23:41] [INFO] red.main: Keyboard interrupt detected. Quitting...
[2019-11-10 18:24:43] [ERROR] red: Package loading failed
Traceback (most recent call last):
  File "/usr/local/lib/python3.7/site-packages/redbot/core/core_commands.py", line 106, in _load
    await bot.load_extension(spec)
  File "/usr/local/lib/python3.7/site-packages/redbot/core/bot.py", line 296, in load_extension
    raise discord.ClientException(f"extension {name} does not have a setup function")
discord.errors.ClientException: extension cryptic does not have a setup function
[2019-11-10 18:29:19] [ERROR] red: Package loading failed
Traceback (most recent call last):
  File "/usr/local/lib/python3.7/site-packages/redbot/core/core_commands.py", line 106, in _load
    await bot.load_extension(spec)
  File "/usr/local/lib/python3.7/site-packages/redbot/core/bot.py", line 296, in load_extension
    raise discord.ClientException(f"extension {name} does not have a setup function")
discord.errors.ClientException: extension cryptic does not have a setup function
[2019-11-10 18:33:04] [ERROR] red: Package loading failed
Traceback (most recent call last):
  File "/usr/local/lib/python3.7/site-packages/redbot/core/core_commands.py", line 105, in _load
    self._cleanup_and_refresh_modules(spec.name)
  File "/usr/local/lib/python3.7/site-packages/redbot/core/core_commands.py", line 146, in _cleanup_and_refresh_modules
    maybe_reload(m)
  File "/usr/local/lib/python3.7/site-packages/redbot/core/core_commands.py", line 141, in maybe_reload
    importlib._bootstrap._exec(lib.__spec__, lib)
  File "<frozen importlib._bootstrap>", line 630, in _exec
  File "<frozen importlib._bootstrap_external>", line 724, in exec_module
  File "<frozen importlib._bootstrap_external>", line 859, in get_code
  File "<frozen importlib._bootstrap_external>", line 916, in get_data
FileNotFoundError: [Errno 2] No such file or directory: '/Users/vutheduc/Documents/Projects/PuzzleSoc/Social/Discord/CrypticBot/cogs/cryptic/cryptic.py'
[2019-11-10 18:33:39] [ERROR] red: Package loading failed
Traceback (most recent call last):
  File "/usr/local/lib/python3.7/site-packages/redbot/core/core_commands.py", line 105, in _load
    self._cleanup_and_refresh_modules(spec.name)
  File "/usr/local/lib/python3.7/site-packages/redbot/core/core_commands.py", line 146, in _cleanup_and_refresh_modules
    maybe_reload(m)
  File "/usr/local/lib/python3.7/site-packages/redbot/core/core_commands.py", line 141, in maybe_reload
    importlib._bootstrap._exec(lib.__spec__, lib)
  File "<frozen importlib._bootstrap>", line 630, in _exec
  File "<frozen importlib._bootstrap_external>", line 724, in exec_module
  File "<frozen importlib._bootstrap_external>", line 859, in get_code
  File "<frozen importlib._bootstrap_external>", line 916, in get_data
FileNotFoundError: [Errno 2] No such file or directory: '/Users/vutheduc/Documents/Projects/PuzzleSoc/Social/Discord/CrypticBot/cogs/cryptic/cryptic.py'
[2019-11-10 18:35:02] [ERROR] red: Package loading failed
Traceback (most recent call last):
  File "/usr/local/lib/python3.7/site-packages/redbot/core/core_commands.py", line 105, in _load
    self._cleanup_and_refresh_modules(spec.name)
  File "/usr/local/lib/python3.7/site-packages/redbot/core/core_commands.py", line 146, in _cleanup_and_refresh_modules
    maybe_reload(m)
  File "/usr/local/lib/python3.7/site-packages/redbot/core/core_commands.py", line 141, in maybe_reload
    importlib._bootstrap._exec(lib.__spec__, lib)
  File "<frozen importlib._bootstrap>", line 630, in _exec
  File "<frozen importlib._bootstrap_external>", line 724, in exec_module
  File "<frozen importlib._bootstrap_external>", line 859, in get_code
  File "<frozen importlib._bootstrap_external>", line 916, in get_data
FileNotFoundError: [Errno 2] No such file or directory: '/Users/vutheduc/Documents/Projects/PuzzleSoc/Social/Discord/CrypticBot/cogs/cryptic/cryptic.py'
[2019-11-10 18:35:30] [ERROR] red: Package loading failed
Traceback (most recent call last):
  File "/usr/local/lib/python3.7/site-packages/redbot/core/core_commands.py", line 106, in _load
    await bot.load_extension(spec)
  File "/usr/local/lib/python3.7/site-packages/redbot/core/bot.py", line 296, in load_extension
    raise discord.ClientException(f"extension {name} does not have a setup function")
discord.errors.ClientException: extension cryptic does not have a setup function
[2019-11-10 18:51:59] [ERROR] red: Package loading failed
Traceback (most recent call last):
  File "/usr/local/lib/python3.7/site-packages/redbot/core/core_commands.py", line 106, in _load
    await bot.load_extension(spec)
  File "/usr/local/lib/python3.7/site-packages/redbot/core/bot.py", line 296, in load_extension
    raise discord.ClientException(f"extension {name} does not have a setup function")
discord.errors.ClientException: extension cryptic does not have a setup function
[2019-11-10 19:05:03] [ERROR] red: Package loading failed
Traceback (most recent call last):
  File "/usr/local/lib/python3.7/site-packages/redbot/core/core_commands.py", line 106, in _load
    await bot.load_extension(spec)
  File "/usr/local/lib/python3.7/site-packages/redbot/core/bot.py", line 293, in load_extension
    lib = spec.loader.load_module()
  File "<frozen importlib._bootstrap_external>", line 407, in _check_name_wrapper
  File "<frozen importlib._bootstrap_external>", line 907, in load_module
  File "<frozen importlib._bootstrap_external>", line 732, in load_module
  File "<frozen importlib._bootstrap>", line 265, in _load_module_shim
  File "<frozen importlib._bootstrap>", line 696, in _load
  File "<frozen importlib._bootstrap>", line 677, in _load_unlocked
  File "<frozen importlib._bootstrap_external>", line 728, in exec_module
  File "<frozen importlib._bootstrap>", line 219, in _call_with_frames_removed
  File "/Users/vutheduc/Documents/Projects/PuzzleSoc/Social/Discord/CrypticBot/mycogs/aikaterna-cogs/dictionary/__init__.py", line 1, in <module>
    from .dictionary import Dictionary
  File "/Users/vutheduc/Documents/Projects/PuzzleSoc/Social/Discord/CrypticBot/mycogs/aikaterna-cogs/dictionary/dictionary.py", line 2, in <module>
    from bs4 import BeautifulSoup
ModuleNotFoundError: No module named 'bs4'
[2019-11-11 10:15:38] [INFO] red.main: Keyboard interrupt detected. Quitting...
[2019-11-11 12:10:27] [INFO] red.main: Keyboard interrupt detected. Quitting...
[2019-11-11 19:31:13] [ERROR] red: Failed to load package cryptic
Traceback (most recent call last):
  File "C:\Users\cemalk\AppData\Roaming\Python\Python37\site-packages\redbot\core\events.py", line 71, in on_ready
    await bot.load_extension(spec)
  File "C:\Users\cemalk\AppData\Roaming\Python\Python37\site-packages\redbot\core\bot.py", line 289, in load_extension
    name = spec.name.split(".")[-1]
AttributeError: 'NoneType' object has no attribute 'name'
[2019-11-11 19:31:13] [ERROR] red: Failed to load package werewolf
Traceback (most recent call last):
  File "C:\Users\cemalk\AppData\Roaming\Python\Python37\site-packages\redbot\core\events.py", line 71, in on_ready
    await bot.load_extension(spec)
  File "C:\Users\cemalk\AppData\Roaming\Python\Python37\site-packages\redbot\core\bot.py", line 289, in load_extension
    name = spec.name.split(".")[-1]
AttributeError: 'NoneType' object has no attribute 'name'
[2019-11-13 11:32:04] [CRITICAL] red.main: This token doesn't seem to be valid.
[2019-11-13 15:09:59] [CRITICAL] red.main: Fatal exception
Traceback (most recent call last):
  File "/usr/local/lib/python3.7/site-packages/discord/gateway.py", line 468, in poll_event
    msg = await self.recv()
  File "/usr/local/lib/python3.7/site-packages/websockets/protocol.py", line 350, in recv
    yield from self.ensure_open()
  File "/usr/local/lib/python3.7/site-packages/websockets/protocol.py", line 512, in ensure_open
    self.close_code, self.close_reason) from self.transfer_data_exc
websockets.exceptions.ConnectionClosed: WebSocket connection is closed: code = 4004 (private use), reason = Authentication failed.

The above exception was the direct cause of the following exception:

Traceback (most recent call last):
  File "/usr/local/lib/python3.7/site-packages/redbot/__main__.py", line 150, in main
    loop.run_until_complete(red.start(token, bot=True))
  File "uvloop/loop.pyx", line 1417, in uvloop.loop.Loop.run_until_complete
  File "/usr/local/lib/python3.7/site-packages/discord/client.py", line 543, in start
    await self.connect(reconnect=reconnect)
  File "/usr/local/lib/python3.7/site-packages/discord/client.py", line 457, in connect
    await self._connect()
  File "/usr/local/lib/python3.7/site-packages/discord/shard.py", line 274, in _connect
    f.result()
  File "/usr/local/lib/python3.7/site-packages/discord/shard.py", line 78, in poll
    await self.ws.poll_event()
  File "/usr/local/lib/python3.7/site-packages/discord/gateway.py", line 476, in poll_event
    raise ConnectionClosed(exc, shard_id=self.shard_id) from exc
discord.errors.ConnectionClosed: WebSocket connection is closed: code = 4004 (private use), reason = Authentication failed.
[2019-11-13 15:10:25] [CRITICAL] red.main: This token doesn't seem to be valid.
[2019-11-13 15:11:31] [CRITICAL] red.main: This token doesn't seem to be valid.
[2019-11-13 22:09:07] [ERROR] red: Package loading failed
Traceback (most recent call last):
  File "/usr/local/lib/python3.7/site-packages/redbot/core/core_commands.py", line 106, in _load
    await bot.load_extension(spec)
  File "/usr/local/lib/python3.7/site-packages/redbot/core/bot.py", line 293, in load_extension
    lib = spec.loader.load_module()
  File "<frozen importlib._bootstrap_external>", line 407, in _check_name_wrapper
  File "<frozen importlib._bootstrap_external>", line 907, in load_module
  File "<frozen importlib._bootstrap_external>", line 732, in load_module
  File "<frozen importlib._bootstrap>", line 265, in _load_module_shim
  File "<frozen importlib._bootstrap>", line 696, in _load
  File "<frozen importlib._bootstrap>", line 677, in _load_unlocked
  File "<frozen importlib._bootstrap_external>", line 728, in exec_module
  File "<frozen importlib._bootstrap>", line 219, in _call_with_frames_removed
  File "/Users/vutheduc/Documents/Projects/PuzzleSoc/Social/Discord/CrypticBot/mycogs/cryptic/__init__.py", line 1, in <module>
    from .cryptic import Cryptic
  File "/Users/vutheduc/Documents/Projects/PuzzleSoc/Social/Discord/CrypticBot/mycogs/cryptic/cryptic.py", line 13, in <module>
    class Cryptic(commands.Cog):
  File "/Users/vutheduc/Documents/Projects/PuzzleSoc/Social/Discord/CrypticBot/mycogs/cryptic/cryptic.py", line 92, in Cryptic
    @cryptic.command(name="help")
AttributeError: 'Command' object has no attribute 'command'
[2019-11-13 22:09:39] [ERROR] red: Package loading failed
Traceback (most recent call last):
  File "/usr/local/lib/python3.7/site-packages/redbot/core/core_commands.py", line 106, in _load
    await bot.load_extension(spec)
  File "/usr/local/lib/python3.7/site-packages/redbot/core/bot.py", line 293, in load_extension
    lib = spec.loader.load_module()
  File "<frozen importlib._bootstrap_external>", line 407, in _check_name_wrapper
  File "<frozen importlib._bootstrap_external>", line 907, in load_module
  File "<frozen importlib._bootstrap_external>", line 732, in load_module
  File "<frozen importlib._bootstrap>", line 265, in _load_module_shim
  File "<frozen importlib._bootstrap>", line 696, in _load
  File "<frozen importlib._bootstrap>", line 677, in _load_unlocked
  File "<frozen importlib._bootstrap_external>", line 728, in exec_module
  File "<frozen importlib._bootstrap>", line 219, in _call_with_frames_removed
  File "/Users/vutheduc/Documents/Projects/PuzzleSoc/Social/Discord/CrypticBot/mycogs/cryptic/__init__.py", line 1, in <module>
    from .cryptic import Cryptic
  File "/Users/vutheduc/Documents/Projects/PuzzleSoc/Social/Discord/CrypticBot/mycogs/cryptic/cryptic.py", line 13, in <module>
    class Cryptic(commands.Cog):
  File "/Users/vutheduc/Documents/Projects/PuzzleSoc/Social/Discord/CrypticBot/mycogs/cryptic/cryptic.py", line 109, in Cryptic
    @checks.mod_or_permissions(administrator=True)
NameError: name 'checks' is not defined
[2019-11-13 22:10:31] [ERROR] red: Package loading failed
Traceback (most recent call last):
  File "/usr/local/lib/python3.7/site-packages/redbot/core/core_commands.py", line 106, in _load
    await bot.load_extension(spec)
  File "/usr/local/lib/python3.7/site-packages/redbot/core/bot.py", line 302, in load_extension
    lib.setup(self)
  File "/Users/vutheduc/Documents/Projects/PuzzleSoc/Social/Discord/CrypticBot/mycogs/cryptic/__init__.py", line 4, in setup
    bot.add_cog(Cryptic())
  File "/Users/vutheduc/Documents/Projects/PuzzleSoc/Social/Discord/CrypticBot/mycogs/cryptic/cryptic.py", line 17, in __init__
    self._all_clues = self._load_clues()
  File "/Users/vutheduc/Documents/Projects/PuzzleSoc/Social/Discord/CrypticBot/mycogs/cryptic/cryptic.py", line 21, in _load_clues
    with open('data/cryptics.yaml', 'r') as f:
FileNotFoundError: [Errno 2] No such file or directory: 'data/cryptics.yaml'
[2019-11-13 22:10:57] [ERROR] red: Package loading failed
Traceback (most recent call last):
  File "/usr/local/lib/python3.7/site-packages/redbot/core/core_commands.py", line 106, in _load
    await bot.load_extension(spec)
  File "/usr/local/lib/python3.7/site-packages/redbot/core/bot.py", line 302, in load_extension
    lib.setup(self)
  File "/Users/vutheduc/Documents/Projects/PuzzleSoc/Social/Discord/CrypticBot/mycogs/cryptic/__init__.py", line 4, in setup
    bot.add_cog(Cryptic())
  File "/Users/vutheduc/Documents/Projects/PuzzleSoc/Social/Discord/CrypticBot/mycogs/cryptic/cryptic.py", line 17, in __init__
    self._all_clues = self._load_clues()
  File "/Users/vutheduc/Documents/Projects/PuzzleSoc/Social/Discord/CrypticBot/mycogs/cryptic/cryptic.py", line 21, in _load_clues
    with open('./data/cryptics.yaml', 'r') as f:
FileNotFoundError: [Errno 2] No such file or directory: './data/cryptics.yaml'
[2019-11-13 22:16:40] [ERROR] red: Package loading failed
Traceback (most recent call last):
  File "/usr/local/lib/python3.7/site-packages/redbot/core/core_commands.py", line 106, in _load
    await bot.load_extension(spec)
  File "/usr/local/lib/python3.7/site-packages/redbot/core/bot.py", line 293, in load_extension
    lib = spec.loader.load_module()
  File "<frozen importlib._bootstrap_external>", line 407, in _check_name_wrapper
  File "<frozen importlib._bootstrap_external>", line 907, in load_module
  File "<frozen importlib._bootstrap_external>", line 732, in load_module
  File "<frozen importlib._bootstrap>", line 265, in _load_module_shim
  File "<frozen importlib._bootstrap>", line 696, in _load
  File "<frozen importlib._bootstrap>", line 677, in _load_unlocked
  File "<frozen importlib._bootstrap_external>", line 728, in exec_module
  File "<frozen importlib._bootstrap>", line 219, in _call_with_frames_removed
  File "/Users/vutheduc/Documents/Projects/PuzzleSoc/Social/Discord/CrypticBot/mycogs/cryptic/__init__.py", line 1, in <module>
    from .cryptic import Cryptic
  File "/Users/vutheduc/Documents/Projects/PuzzleSoc/Social/Discord/CrypticBot/mycogs/cryptic/cryptic.py", line 14, in <module>
    class Cryptic(commands.Cog):
  File "/Users/vutheduc/Documents/Projects/PuzzleSoc/Social/Discord/CrypticBot/mycogs/cryptic/cryptic.py", line 22, in Cryptic
    def _load_clues(self) -> List[pathlib.Path]:
NameError: name 'List' is not defined
[2019-11-13 22:29:14] [ERROR] red: Package loading failed
Traceback (most recent call last):
  File "/usr/local/lib/python3.7/site-packages/redbot/core/core_commands.py", line 106, in _load
    await bot.load_extension(spec)
  File "/usr/local/lib/python3.7/site-packages/redbot/core/bot.py", line 302, in load_extension
    lib.setup(self)
  File "/Users/vutheduc/Documents/Projects/PuzzleSoc/Social/Discord/CrypticBot/mycogs/cryptic/__init__.py", line 4, in setup
    bot.add_cog(Cryptic())
  File "/Users/vutheduc/Documents/Projects/PuzzleSoc/Social/Discord/CrypticBot/mycogs/cryptic/cryptic.py", line 19, in __init__
    self._all_clues = self._load_clues()
  File "/Users/vutheduc/Documents/Projects/PuzzleSoc/Social/Discord/CrypticBot/mycogs/cryptic/cryptic.py", line 24, in _load_clues
    with open('cryptics.yaml', 'r', encoding='utf-8') as f:
FileNotFoundError: [Errno 2] No such file or directory: 'cryptics.yaml'
[2019-11-13 22:34:00] [ERROR] red: Package loading failed
Traceback (most recent call last):
  File "/usr/local/lib/python3.7/site-packages/redbot/core/core_commands.py", line 106, in _load
    await bot.load_extension(spec)
  File "/usr/local/lib/python3.7/site-packages/redbot/core/bot.py", line 302, in load_extension
    lib.setup(self)
  File "/Users/vutheduc/Documents/Projects/PuzzleSoc/Social/Discord/CrypticBot/mycogs/cryptic/__init__.py", line 4, in setup
    bot.add_cog(Cryptic())
  File "/Users/vutheduc/Documents/Projects/PuzzleSoc/Social/Discord/CrypticBot/mycogs/cryptic/cryptic.py", line 19, in __init__
    self._all_clues = self._load_clues()
  File "/Users/vutheduc/Documents/Projects/PuzzleSoc/Social/Discord/CrypticBot/mycogs/cryptic/cryptic.py", line 25, in _load_clues
    with open(path + 'cryptics.yaml', 'r', encoding='utf-8') as f:
TypeError: unsupported operand type(s) for +: 'PosixPath' and 'str'
[2019-11-13 22:34:38] [ERROR] red: Exception in command 'cryptic'
Traceback (most recent call last):
  File "/usr/local/lib/python3.7/site-packages/discord/ext/commands/core.py", line 79, in wrapped
    ret = await coro(*args, **kwargs)
  File "/Users/vutheduc/Documents/Projects/PuzzleSoc/Social/Discord/CrypticBot/mycogs/cryptic/cryptic.py", line 41, in cryptic
    ans = self._all_clues[clue]
KeyError: None
[2019-11-13 22:35:54] [ERROR] red: Exception in command 'cryptic'
Traceback (most recent call last):
  File "/usr/local/lib/python3.7/site-packages/discord/ext/commands/core.py", line 79, in wrapped
    ret = await coro(*args, **kwargs)
  File "/Users/vutheduc/Documents/Projects/PuzzleSoc/Social/Discord/CrypticBot/mycogs/cryptic/cryptic.py", line 41, in cryptic
    clue = random.choice(self._all_clues.keys())
KeyError: None
[2019-11-13 22:36:12] [ERROR] red: Exception in command 'cryptic'
Traceback (most recent call last):
  File "/usr/local/lib/python3.7/site-packages/discord/ext/commands/core.py", line 79, in wrapped
    ret = await coro(*args, **kwargs)
  File "/Users/vutheduc/Documents/Projects/PuzzleSoc/Social/Discord/CrypticBot/mycogs/cryptic/cryptic.py", line 42, in cryptic
    ans = self._all_clues[clue]
KeyError: None
[2019-11-13 22:36:46] [ERROR] red: Exception in command 'cryptic'
Traceback (most recent call last):
  File "/usr/local/lib/python3.7/site-packages/discord/ext/commands/core.py", line 79, in wrapped
    ret = await coro(*args, **kwargs)
  File "/Users/vutheduc/Documents/Projects/PuzzleSoc/Social/Discord/CrypticBot/mycogs/cryptic/cryptic.py", line 42, in cryptic
    ans = self._all_clues[clue]
KeyError: None
[2019-11-13 22:36:53] [ERROR] red: Exception in command 'cryptic'
Traceback (most recent call last):
  File "/usr/local/lib/python3.7/site-packages/discord/ext/commands/core.py", line 79, in wrapped
    ret = await coro(*args, **kwargs)
  File "/Users/vutheduc/Documents/Projects/PuzzleSoc/Social/Discord/CrypticBot/mycogs/cryptic/cryptic.py", line 41, in cryptic
    clue = random.choice(self._all_clues.keys())
  File "/usr/local/Cellar/python/3.7.0/Frameworks/Python.framework/Versions/3.7/lib/python3.7/random.py", line 262, in choice
    return seq[i]
TypeError: 'dict_keys' object does not support indexing
[2019-11-13 22:37:15] [ERROR] red: Exception in command 'cryptic'
Traceback (most recent call last):
  File "/usr/local/lib/python3.7/site-packages/discord/ext/commands/core.py", line 79, in wrapped
    ret = await coro(*args, **kwargs)
  File "/Users/vutheduc/Documents/Projects/PuzzleSoc/Social/Discord/CrypticBot/mycogs/cryptic/cryptic.py", line 54, in cryptic
    continue_ = await self.wait_for_answer(ans, 0)
  File "/Users/vutheduc/Documents/Projects/PuzzleSoc/Social/Discord/CrypticBot/mycogs/cryptic/cryptic.py", line 78, in wait_for_answer
    message = await self.ctx.bot.wait_for(
AttributeError: 'Cryptic' object has no attribute 'ctx'
[2019-11-13 22:38:37] [ERROR] red: Exception in command 'cryptic'
Traceback (most recent call last):
  File "/usr/local/lib/python3.7/site-packages/discord/ext/commands/core.py", line 79, in wrapped
    ret = await coro(*args, **kwargs)
  File "/Users/vutheduc/Documents/Projects/PuzzleSoc/Social/Discord/CrypticBot/mycogs/cryptic/cryptic.py", line 55, in cryptic
    continue_ = await self.wait_for_answer(ans, 0)
  File "/Users/vutheduc/Documents/Projects/PuzzleSoc/Social/Discord/CrypticBot/mycogs/cryptic/cryptic.py", line 80, in wait_for_answer
    "message", check=self.check_answer(answer), timeout=delay
  File "/Users/vutheduc/Documents/Projects/PuzzleSoc/Social/Discord/CrypticBot/mycogs/cryptic/cryptic.py", line 96, in check_answer
    def _pred(message: discord.Message):
NameError: name 'discord' is not defined
[2019-11-13 22:39:33] [INFO] red.main: Keyboard interrupt detected. Quitting...
[2019-11-13 22:48:12] [ERROR] red: Package loading failed
Traceback (most recent call last):
  File "/usr/local/lib/python3.7/site-packages/redbot/core/core_commands.py", line 106, in _load
    await bot.load_extension(spec)
  File "/usr/local/lib/python3.7/site-packages/redbot/core/bot.py", line 293, in load_extension
    lib = spec.loader.load_module()
  File "<frozen importlib._bootstrap_external>", line 407, in _check_name_wrapper
  File "<frozen importlib._bootstrap_external>", line 907, in load_module
  File "<frozen importlib._bootstrap_external>", line 732, in load_module
  File "<frozen importlib._bootstrap>", line 265, in _load_module_shim
  File "<frozen importlib._bootstrap>", line 696, in _load
  File "<frozen importlib._bootstrap>", line 677, in _load_unlocked
  File "<frozen importlib._bootstrap_external>", line 728, in exec_module
  File "<frozen importlib._bootstrap>", line 219, in _call_with_frames_removed
  File "/Users/vutheduc/Documents/Projects/PuzzleSoc/Social/Discord/CrypticBot/mycogs/cryptic/__init__.py", line 1, in <module>
    from .cryptic import Cryptic
  File "/Users/vutheduc/Documents/Projects/PuzzleSoc/Social/Discord/CrypticBot/mycogs/cryptic/cryptic.py", line 26, in <module>
    class Cryptic(commands.Cog):
  File "/Users/vutheduc/Documents/Projects/PuzzleSoc/Social/Discord/CrypticBot/mycogs/cryptic/cryptic.py", line 115, in Cryptic
    @cryptic.command(name="help")
AttributeError: 'Command' object has no attribute 'command'
[2019-11-13 22:55:00] [ERROR] red: Exception in command 'help'
Traceback (most recent call last):
  File "/usr/local/lib/python3.7/site-packages/redbot/core/commands/help.py", line 560, in send_pages
    await destination.send(page)
  File "/usr/local/lib/python3.7/site-packages/redbot/core/commands/context.py", line 64, in send
    return await super().send(content=content, **kwargs)
  File "/usr/local/lib/python3.7/site-packages/discord/abc.py", line 823, in send
    data = await state.http.send_message(channel.id, content, tts=tts, embed=embed, nonce=nonce)
  File "/usr/local/lib/python3.7/site-packages/discord/http.py", line 218, in request
    raise Forbidden(r, data)
discord.errors.Forbidden: 403 FORBIDDEN (error code: 50013): Missing Permissions

During handling of the above exception, another exception occurred:

Traceback (most recent call last):
  File "/usr/local/lib/python3.7/site-packages/discord/ext/commands/core.py", line 79, in wrapped
    ret = await coro(*args, **kwargs)
  File "/usr/local/lib/python3.7/site-packages/redbot/core/commands/help.py", line 586, in red_help
    await ctx.bot.send_help_for(ctx, thing_to_get_help_for)
  File "/usr/local/lib/python3.7/site-packages/redbot/core/bot.py", line 176, in send_help_for
    return await self._help_formatter.send_help(ctx, help_for)
  File "/usr/local/lib/python3.7/site-packages/redbot/core/commands/help.py", line 88, in send_help
    await self.format_bot_help(ctx)
  File "/usr/local/lib/python3.7/site-packages/redbot/core/commands/help.py", line 427, in format_bot_help
    await self.send_pages(ctx, pages, embed=False)
  File "/usr/local/lib/python3.7/site-packages/redbot/core/commands/help.py", line 564, in send_pages
    "I couldn't send the help message to you in DM. "
  File "/usr/local/lib/python3.7/site-packages/redbot/core/commands/context.py", line 64, in send
    return await super().send(content=content, **kwargs)
  File "/usr/local/lib/python3.7/site-packages/discord/abc.py", line 823, in send
    data = await state.http.send_message(channel.id, content, tts=tts, embed=embed, nonce=nonce)
  File "/usr/local/lib/python3.7/site-packages/discord/http.py", line 218, in request
    raise Forbidden(r, data)
discord.errors.Forbidden: 403 FORBIDDEN (error code: 50013): Missing Permissions
[2019-11-13 22:58:02] [ERROR] red: Exception in command 'cryptic'
Traceback (most recent call last):
  File "/usr/local/lib/python3.7/site-packages/discord/ext/commands/core.py", line 79, in wrapped
    ret = await coro(*args, **kwargs)
  File "/Users/vutheduc/Documents/Projects/PuzzleSoc/Social/Discord/CrypticBot/mycogs/cryptic/cryptic.py", line 67, in cryptic
    continue_ = await self.wait_for_answer(ans, 500)
  File "/Users/vutheduc/Documents/Projects/PuzzleSoc/Social/Discord/CrypticBot/mycogs/cryptic/cryptic.py", line 102, in wait_for_answer
    bold(f'{clue} ({ans_len})') + '\n\n'
  File "/usr/local/lib/python3.7/site-packages/redbot/core/commands/context.py", line 64, in send
    return await super().send(content=content, **kwargs)
  File "/usr/local/lib/python3.7/site-packages/discord/abc.py", line 823, in send
    data = await state.http.send_message(channel.id, content, tts=tts, embed=embed, nonce=nonce)
  File "/usr/local/lib/python3.7/site-packages/discord/http.py", line 220, in request
    raise NotFound(r, data)
discord.errors.NotFound: 404 NOT FOUND (error code: 10003): Unknown Channel
[2019-11-13 23:05:29] [ERROR] red: Exception in command 'help'
Traceback (most recent call last):
  File "/usr/local/lib/python3.7/site-packages/redbot/core/commands/help.py", line 560, in send_pages
    await destination.send(page)
  File "/usr/local/lib/python3.7/site-packages/redbot/core/commands/context.py", line 64, in send
    return await super().send(content=content, **kwargs)
  File "/usr/local/lib/python3.7/site-packages/discord/abc.py", line 823, in send
    data = await state.http.send_message(channel.id, content, tts=tts, embed=embed, nonce=nonce)
  File "/usr/local/lib/python3.7/site-packages/discord/http.py", line 218, in request
    raise Forbidden(r, data)
discord.errors.Forbidden: 403 FORBIDDEN (error code: 50013): Missing Permissions

During handling of the above exception, another exception occurred:

Traceback (most recent call last):
  File "/usr/local/lib/python3.7/site-packages/discord/ext/commands/core.py", line 79, in wrapped
    ret = await coro(*args, **kwargs)
  File "/usr/local/lib/python3.7/site-packages/redbot/core/commands/help.py", line 586, in red_help
    await ctx.bot.send_help_for(ctx, thing_to_get_help_for)
  File "/usr/local/lib/python3.7/site-packages/redbot/core/bot.py", line 176, in send_help_for
    return await self._help_formatter.send_help(ctx, help_for)
  File "/usr/local/lib/python3.7/site-packages/redbot/core/commands/help.py", line 88, in send_help
    await self.format_bot_help(ctx)
  File "/usr/local/lib/python3.7/site-packages/redbot/core/commands/help.py", line 427, in format_bot_help
    await self.send_pages(ctx, pages, embed=False)
  File "/usr/local/lib/python3.7/site-packages/redbot/core/commands/help.py", line 564, in send_pages
    "I couldn't send the help message to you in DM. "
  File "/usr/local/lib/python3.7/site-packages/redbot/core/commands/context.py", line 64, in send
    return await super().send(content=content, **kwargs)
  File "/usr/local/lib/python3.7/site-packages/discord/abc.py", line 823, in send
    data = await state.http.send_message(channel.id, content, tts=tts, embed=embed, nonce=nonce)
  File "/usr/local/lib/python3.7/site-packages/discord/http.py", line 218, in request
    raise Forbidden(r, data)
discord.errors.Forbidden: 403 FORBIDDEN (error code: 50013): Missing Permissions
[2019-11-13 23:05:46] [ERROR] red: Exception in command 'trivia'
Traceback (most recent call last):
  File "/usr/local/lib/python3.7/site-packages/redbot/core/commands/help.py", line 560, in send_pages
    await destination.send(page)
  File "/usr/local/lib/python3.7/site-packages/redbot/core/commands/context.py", line 64, in send
    return await super().send(content=content, **kwargs)
  File "/usr/local/lib/python3.7/site-packages/discord/abc.py", line 823, in send
    data = await state.http.send_message(channel.id, content, tts=tts, embed=embed, nonce=nonce)
  File "/usr/local/lib/python3.7/site-packages/discord/http.py", line 218, in request
    raise Forbidden(r, data)
discord.errors.Forbidden: 403 FORBIDDEN (error code: 50013): Missing Permissions

During handling of the above exception, another exception occurred:

Traceback (most recent call last):
  File "/usr/local/lib/python3.7/site-packages/discord/ext/commands/core.py", line 79, in wrapped
    ret = await coro(*args, **kwargs)
  File "/Users/vutheduc/Documents/Projects/PuzzleSoc/Social/Discord/CrypticBot/mycogs/trivia2/trivia.py", line 182, in trivia
    await ctx.send_help()
  File "/usr/local/lib/python3.7/site-packages/redbot/core/commands/context.py", line 71, in send_help
    await self.bot.send_help_for(self, command)
  File "/usr/local/lib/python3.7/site-packages/redbot/core/bot.py", line 176, in send_help_for
    return await self._help_formatter.send_help(ctx, help_for)
  File "/usr/local/lib/python3.7/site-packages/redbot/core/commands/help.py", line 106, in send_help
    await self.format_command_help(ctx, help_for)
  File "/usr/local/lib/python3.7/site-packages/redbot/core/commands/help.py", line 233, in format_command_help
    await self.send_pages(ctx, pages, embed=False)
  File "/usr/local/lib/python3.7/site-packages/redbot/core/commands/help.py", line 564, in send_pages
    "I couldn't send the help message to you in DM. "
  File "/usr/local/lib/python3.7/site-packages/redbot/core/commands/context.py", line 64, in send
    return await super().send(content=content, **kwargs)
  File "/usr/local/lib/python3.7/site-packages/discord/abc.py", line 823, in send
    data = await state.http.send_message(channel.id, content, tts=tts, embed=embed, nonce=nonce)
  File "/usr/local/lib/python3.7/site-packages/discord/http.py", line 218, in request
    raise Forbidden(r, data)
discord.errors.Forbidden: 403 FORBIDDEN (error code: 50013): Missing Permissions
[2019-11-13 23:15:48] [ERROR] red: Exception in command 'cryptic'
Traceback (most recent call last):
  File "/usr/local/lib/python3.7/site-packages/discord/ext/commands/core.py", line 79, in wrapped
    ret = await coro(*args, **kwargs)
  File "/Users/vutheduc/Documents/Projects/PuzzleSoc/Social/Discord/CrypticBot/mycogs/cryptic/cryptic.py", line 57, in cryptic
    ans_len = ', '.join([len(a) for a in ans.split()])
TypeError: sequence item 0: expected str instance, int found
[2019-11-13 23:21:20] [ERROR] red: Exception in command 'cryptic'
Traceback (most recent call last):
  File "/usr/local/lib/python3.7/site-packages/discord/ext/commands/core.py", line 79, in wrapped
    ret = await coro(*args, **kwargs)
  File "/Users/vutheduc/Documents/Projects/PuzzleSoc/Social/Discord/CrypticBot/mycogs/cryptic/cryptic.py", line 63, in cryptic
    await ctx.send(text + "\n\n" + bold(f'{clue} ({ans_len})'))
UnboundLocalError: local variable 'text' referenced before assignment
[2019-11-13 23:22:26] [ERROR] red: Exception in command 'help'
Traceback (most recent call last):
  File "/usr/local/lib/python3.7/site-packages/redbot/core/commands/help.py", line 560, in send_pages
    await destination.send(page)
  File "/usr/local/lib/python3.7/site-packages/redbot/core/commands/context.py", line 64, in send
    return await super().send(content=content, **kwargs)
  File "/usr/local/lib/python3.7/site-packages/discord/abc.py", line 823, in send
    data = await state.http.send_message(channel.id, content, tts=tts, embed=embed, nonce=nonce)
  File "/usr/local/lib/python3.7/site-packages/discord/http.py", line 218, in request
    raise Forbidden(r, data)
discord.errors.Forbidden: 403 FORBIDDEN (error code: 50013): Missing Permissions

During handling of the above exception, another exception occurred:

Traceback (most recent call last):
  File "/usr/local/lib/python3.7/site-packages/discord/ext/commands/core.py", line 79, in wrapped
    ret = await coro(*args, **kwargs)
  File "/usr/local/lib/python3.7/site-packages/redbot/core/commands/help.py", line 586, in red_help
    await ctx.bot.send_help_for(ctx, thing_to_get_help_for)
  File "/usr/local/lib/python3.7/site-packages/redbot/core/bot.py", line 176, in send_help_for
    return await self._help_formatter.send_help(ctx, help_for)
  File "/usr/local/lib/python3.7/site-packages/redbot/core/commands/help.py", line 88, in send_help
    await self.format_bot_help(ctx)
  File "/usr/local/lib/python3.7/site-packages/redbot/core/commands/help.py", line 427, in format_bot_help
    await self.send_pages(ctx, pages, embed=False)
  File "/usr/local/lib/python3.7/site-packages/redbot/core/commands/help.py", line 564, in send_pages
    "I couldn't send the help message to you in DM. "
  File "/usr/local/lib/python3.7/site-packages/redbot/core/commands/context.py", line 64, in send
    return await super().send(content=content, **kwargs)
  File "/usr/local/lib/python3.7/site-packages/discord/abc.py", line 823, in send
    data = await state.http.send_message(channel.id, content, tts=tts, embed=embed, nonce=nonce)
  File "/usr/local/lib/python3.7/site-packages/discord/http.py", line 218, in request
    raise Forbidden(r, data)
discord.errors.Forbidden: 403 FORBIDDEN (error code: 50013): Missing Permissions
[2019-11-14 21:08:51] [ERROR] red: Exception in command 'cryptic'
Traceback (most recent call last):
  File "/usr/local/lib/python3.7/site-packages/discord/ext/commands/core.py", line 79, in wrapped
    ret = await coro(*args, **kwargs)
  File "/Users/vutheduc/Documents/Projects/PuzzleSoc/Social/Discord/CrypticBot/mycogs/cryptic/cryptic.py", line 72, in cryptic
    text = random.choice(STARTING_TEXTS)
NameError: name 'STARTING_TEXTS' is not defined
